Workbook

Sheet Resumen-Mensual
B2: RESUMEN DE CURTAILMENTS ACUMULADO DE CENTRALES EÓLICAS, SOLARES HIDRÁULICAS DE PASADA, EMBALSES Y SERIES HÍDRICAS AÑO 2026
C4: Resumen Anual / Mensual (GWh)
C6: Acumulado 2026
B7: Eólica | C7: =SUM(C14,F14,I14,L14,O14,R14,U14,X14,AA14,AD14,AG14,AJ14) -> 487.90975 | E7: =IF($C$11=0,"-",+C7/$C$11) -> 0.25672683
B8: Solar | C8: =SUM(C15,F15,I15,L15,O15,R15,U15,X15,AA15,AD15,AG15,AJ15) -> 1381.1686 | E8: =IF($C$11=0,"-",+C8/$C$11) -> 0.72673899 | Y8: =+AJ87/1000-X15 -> 369.68438
B9: Hidro Pasada | C9: =SUM(C16,F16,I16,L16,O16,R16,U16,X16,AA16,AD16,AG16,AJ16) -> 27.246715 | E9: =IF($C$11=0,"-",+C9/$C$11) -> 0.014336592
B10: Hidro Embalse | C10: =SUM(C17,F17,I17,L17,O17,R17,U17,X17,AA17,AD17,AG17,AJ17) -> 4.1765166 | E10: =IF($C$11=0,"-",+C10/$C$11) -> 0.0021975865
B11: Total | C11: =SUM(C7:C10) -> 1900.5016 | E11: =SUM(E7:E10) -> 1
C13: 46023 | F13: 46054 | I13: 46082 | L13: 46113 | O13: 46143 | R13: 46174 | U13: 46204 | X13: 46235 | AA13: 46266 | AD13: 46296 | AG13: 46327 | AJ13: 46357
B14: Eólica | C14: ='Acumulado-Anual-Eólico'!AJ10/1000 -> 195.22041 | E14: =IF($C$18=0,"-",+C14/$C$18) -> 0.24841999 | F14: ='Acumulado-Anual-Eólico'!$AJ$69/1000 -> 165.51954 | H14: =IF($F$18=0,"-",+F14/$F$18) -> 0.26874804 | I14: ='Acumulado-Anual-Eólico'!$AJ$128/1000 -> 127.1698 | K14: =IF($I$18=0,"-",+I14/$I$18) -> 0.2549708 | N14: =IF($L$18=0,"-",+L14/$L$18) -> - | Q14: =IF($O$18=0,"-",+O14/$O$18) -> - | T14: =IF($R$18=0,"-",+R14/$R$18) -> - | W14: =IF($U$18=0,"-",+U14/$U$18) -> - | Z14: =IF($X$18=0,"-",+X14/$X$18) -> - | AC14: =IF($AA$18=0,"-",+AA14/$AA$18) -> - | AF14: =IF($AD$18=0,"-",+AD14/$AD$18) -> - | AI14: =IF($AG$18=0,"-",+AG14/$AG$18) -> - | AL14: =IF($AJ$18=0,"-",+AJ14/$AJ$18) -> -
B15: Solar | C15: ='Acumulado-Anual-Solar'!AJ10/1000 -> 581.15774 | E15: =IF($C$18=0,"-",+C15/$C$18) -> 0.73952923 | F15: ='Acumulado-Anual-Solar'!$AJ$87/1000 -> 430.32649 | H15: =IF($F$18=0,"-",+F15/$F$18) -> 0.69870542 | I15: ='Acumulado-Anual-Solar'!$AJ$164/1000 -> 369.68438 | K15: =IF($I$18=0,"-",+I15/$I$18) -> 0.74120369 | N15: =IF($L$18=0,"-",+L15/$L$18) -> - | Q15: =IF($O$18=0,"-",+O15/$O$18) -> - | T15: =IF($R$18=0,"-",+R15/$R$18) -> - | W15: =IF($U$18=0,"-",+U15/$U$18) -> - | Z15: =IF($X$18=0,"-",+X15/$X$18) -> - | AC15: =IF($AA$18=0,"-",+AA15/$AA$18) -> - | AF15: =IF($AD$18=0,"-",+AD15/$AD$18) -> - | AI15: =IF($AG$18=0,"-",+AG15/$AG$18) -> - | AL15: =IF($AJ$18=0,"-",+AJ15/$AJ$18) -> -
B16: Hidro Pasada | C16: =+'Acumulado-Anual-HP'!AJ10/1000 -> 9.3467424 | E16: =IF($C$18=0,"-",+C16/$C$18) -> 0.011893826 | F16: ='Acumulado-Anual-HP'!$AJ$153/1000 -> 15.991953 | H16: =IF($F$18=0,"-",+F16/$F$18) -> 0.025965551 | I16: ='Acumulado-Anual-HP'!$AJ$296/1000 -> 1.9080195 | K16: =IF($I$18=0,"-",+I16/$I$18) -> 0.0038255094 | N16: =IF($L$18=0,"-",+L16/$L$18) -> - | Q16: =IF($O$18=0,"-",+O16/$O$18) -> - | T16: =IF($R$18=0,"-",+R16/$R$18) -> - | W16: =IF($U$18=0,"-",+U16/$U$18) -> - | Z16: =IF($X$18=0,"-",+X16/$X$18) -> - | AC16: =IF($AA$18=0,"-",+AA16/$AA$18) -> - | AF16: =IF($AD$18=0,"-",+AD16/$AD$18) -> - | AI16: =IF($AG$18=0,"-",+AG16/$AG$18) -> - | AL16: =IF($AJ$18=0,"-",+AJ16/$AJ$18) -> -
B17: Hidro Embalse | C17: ='Acumulado-Anual-HE'!AJ10/1000 -> 0.12334647 | E17: =IF($C$18=0,"-",+C17/$C$18) -> 0.00015695966 | F17: ='Acumulado-Anual-HE'!$AJ$44/1000 -> 4.0531701 | H17: =IF($F$18=0,"-",+F17/$F$18) -> 0.0065809844 | I17: ='Acumulado-Anual-HE'!$AJ$78/1000 -> 0 | K17: =IF($I$18=0,"-",+I17/$I$18) -> 0 | N17: =IF($L$18=0,"-",+L17/$L$18) -> - | Q17: =IF($O$18=0,"-",+O17/$O$18) -> - | T17: =IF($R$18=0,"-",+R17/$R$18) -> - | W17: =IF($U$18=0,"-",+U17/$U$18) -> - | Z17: =IF($X$18=0,"-",+X17/$X$18) -> - | AC17: =IF($AA$18=0,"-",+AA17/$AA$18) -> - | AF17: =IF($AD$18=0,"-",+AD17/$AD$18) -> - | AI17: =IF($AG$18=0,"-",+AG17/$AG$18) -> - | AL17: =IF($AJ$18=0,"-",+AJ17/$AJ$18) -> -
B18: Total | C18: =SUM(C14:D17) -> 785.84824 | E18: =SUM(E14:E17) -> 1 | F18: =SUM(F14:G17) -> 615.89116 | H18: =SUM(H14:H17) -> 1 | I18: =SUM(I14:I17) -> 498.76219 | K18: =SUM(K14:K17) -> 1 | L18: =SUM(L14:L17) -> 0 | N18: =SUM(N14:N17) -> 0 | O18: =SUM(O14:O17) -> 0 | Q18: =SUM(Q14:Q17) -> 0 | R18: =SUM(R14:R17) -> 0 | T18: =SUM(T14:T17) -> 0 | U18: =SUM(U14:U17) -> 0 | W18: =SUM(W14:W17) -> 0 | X18: =SUM(X14:X17) -> 0 | Z18: =SUM(Z14:Z17) -> 0 | AA18: =SUM(AA14:AA17) -> 0 | AC18: =SUM(AC14:AC17) -> 0 | AD18: =SUM(AD14:AD17) -> 0 | AF18: =SUM(AF14:AF17) -> 0 | AG18: =SUM(AG14:AG17) -> 0 | AI18: =SUM(AI14:AI17) -> 0 | AJ18: =SUM(AJ14:AJ17) -> 0 | AL18: =SUM(AL14:AL17) -> 0
B21: RESUMEN DE CURTAILMENTS CENTRALES EÓLICAS, SOLARES, HIDRÁULICAS DE PASADA, EMBALSES Y SERIES HÍDRICAS CORRESPONDIENTE A ENERO 2026 (MWh)
B24: DESGLOSE DIARIO DE CURTAILMENTS DE ENERGÍA EÓLICA
B26: Central / Día | E26: 46082 | F26: =+E26+1 -> 46083 | G26: =+F26+1 -> 46084 | H26: =+G26+1 -> 46085 | I26: =+H26+1 -> 46086 | J26: =+I26+1 -> 46087 | K26: =+J26+1 -> 46088 | L26: =+K26+1 -> 46089 | M26: =+L26+1 -> 46090 | ... AI26: =+AH26+1 -> 46112 | AJ26: Total
B27: Total | E27: =SUM(E28:E81) -> 4699.0964 | F27: =SUM(F28:F81) -> 3036.5574 | G27: =SUM(G28:G81) -> 5801.3038 | H27: =SUM(H28:H81) -> 4772.9443 | I27: =SUM(I28:I81) -> 5002.281 | J27: =SUM(J28:J81) -> 2376.1642 | K27: =SUM(K28:K81) -> 4243.59 | L27: =SUM(L28:L81) -> 6983.2034 | ... AI27: =SUM(AI28:AI81) -> 2223.3306 | AK27: =SUM(AK28:AK81) -> 127169.8
B28: PE-TCHAMMA | E28: ='Resumen-DiarioHorario-Eólico'!AD8 -> 106.789 | F28: ='Resumen-DiarioHorario-Eólico'!AD68 -> 121.961 | G28: ='Resumen-DiarioHorario-Eólico'!AD128 -> 145.62717 | H28: ='Resumen-DiarioHorario-Eólico'!AD188 -> 84.413833 | I28: ='Resumen-DiarioHorario-Eólico'!AD248 -> 165.65133 | J28: ='Resumen-DiarioHorario-Eólico'!AD308 -> 145.74967 | K28: ='Resumen-DiarioHorario-Eólico'!AD368 -> 126.94 | L28: ='Resumen-DiarioHorario-Eólico'!AD428 -> 112.9745 | M28: ='Resumen-DiarioHorario-Eólico'!AD488 -> 166.65583 | N28: ='Resumen-DiarioHorario-Eólico'!AD548 -> 102.27417 | O28: ='Resumen-DiarioHorario-Eólico'!AD608 -> 117.0685 | P28: ='Resumen-DiarioHorario-Eólico'!AD668 -> 105.63867 | Q28: ='Resumen-DiarioHorario-Eólico'!AD728 -> 252.18067 | R28: ='Resumen-DiarioHorario-Eólico'!AD788 -> 220.59217 | S28: ='Resumen-DiarioHorario-Eólico'!AD848 -> 145.597 | T28: ='Resumen-DiarioHorario-Eólico'!AD908 -> 0 | U28: ='Resumen-DiarioHorario-Eólico'!AD968 -> 0 | V28: ='Resumen-DiarioHorario-Eólico'!AD1028 -> 179.50433 | W28: ='Resumen-DiarioHorario-Eólico'!AD1088 -> 210.55467 | X28: ='Resumen-DiarioHorario-Eólico'!AD1148 -> 335.80517 | Y28: ='Resumen-DiarioHorario-Eólico'!AD1208 -> 264.9195 | Z28: ='Resumen-DiarioHorario-Eólico'!AD1268 -> 289.31783 | AA28: ='Resumen-DiarioHorario-Eólico'!AD1328 -> 130.64283 | AB28: ='Resumen-DiarioHorario-Eólico'!AD1388 -> 364.40233 | AC28: ='Resumen-DiarioHorario-Eólico'!AD1448 -> 292.10767 | AD28: ='Resumen-DiarioHorario-Eólico'!AD1508 -> 239.63 | AE28: ='Resumen-DiarioHorario-Eólico'!AD1568 -> 206.91567 | AF28: ='Resumen-DiarioHorario-Eólico'!AD1627 -> 212.91367 | AG28: ='Resumen-DiarioHorario-Eólico'!AD1686 -> 258.03967 | AH28: =+'Resumen-DiarioHorario-Eólico'!AD1745 -> 7.0503333 | AI28: =+'Resumen-DiarioHorario-Eólico'!AD1804 -> 11.759333 | AK28: =SUM(E28:AI28) -> 5123.6765
B29: PE-SIERRAGORDA | E29: ='Resumen-DiarioHorario-Eólico'!AD9 -> 56.322167 | F29: ='Resumen-DiarioHorario-Eólico'!AD69 -> 55.656167 | G29: ='Resumen-DiarioHorario-Eólico'!AD129 -> 41.378333 | H29: ='Resumen-DiarioHorario-Eólico'!AD189 -> 29.7545 | I29: ='Resumen-DiarioHorario-Eólico'!AD249 -> 45.113167 | J29: ='Resumen-DiarioHorario-Eólico'!AD309 -> 52.455667 | K29: ='Resumen-DiarioHorario-Eólico'!AD369 -> 32.37 | L29: ='Resumen-DiarioHorario-Eólico'!AD429 -> 22.688333 | M29: ='Resumen-DiarioHorario-Eólico'!AD489 -> 11.8755 | N29: ='Resumen-DiarioHorario-Eólico'!AD549 -> 29.956333 | O29: ='Resumen-DiarioHorario-Eólico'!AD609 -> 21.7255 | P29: ='Resumen-DiarioHorario-Eólico'!AD669 -> 2.0825 | Q29: ='Resumen-DiarioHorario-Eólico'!AD729 -> 136.74567 | R29: ='Resumen-DiarioHorario-Eólico'!AD789 -> 95.161 | S29: ='Resumen-DiarioHorario-Eólico'!AD849 -> 24.318333 | T29: ='Resumen-DiarioHorario-Eólico'!AD909 -> 23.692833 | U29: ='Resumen-DiarioHorario-Eólico'!AD969 -> 141.4415 | V29: ='Resumen-DiarioHorario-Eólico'!AD1029 -> 137.14867 | W29: ='Resumen-DiarioHorario-Eólico'!AD1089 -> 172.9875 | X29: ='Resumen-DiarioHorario-Eólico'!AD1149 -> 242.77533 | Y29: ='Resumen-DiarioHorario-Eólico'!AD1209 -> 234.23617 | Z29: ='Resumen-DiarioHorario-Eólico'!AD1269 -> 172.412 | AA29: ='Resumen-DiarioHorario-Eólico'!AD1329 -> 217.77533 | AB29: ='Resumen-DiarioHorario-Eólico'!AD1389 -> 157.30267 | AC29: ='Resumen-DiarioHorario-Eólico'!AD1449 -> 172.83867 | AD29: ='Resumen-DiarioHorario-Eólico'!AD1509 -> 183.0365 | AE29: ='Resumen-DiarioHorario-Eólico'!AD1569 -> 163.40417 | AF29: ='Resumen-DiarioHorario-Eólico'!AD1628 -> 220.64683 | AG29: ='Resumen-DiarioHorario-Eólico'!AD1687 -> 126.68917 | AH29: =+'Resumen-DiarioHorario-Eólico'!AD1746 -> 89.485833 | AI29: =+'Resumen-DiarioHorario-Eólico'!AD1805 -> 48.903667 | AK29: =SUM(E29:AI29) -> 3162.38
B30: PE-VALLEDELOSVIENTOS | E30: ='Resumen-DiarioHorario-Eólico'!AD10 -> 249.89683 | F30: ='Resumen-DiarioHorario-Eólico'!AD70 -> 192.47583 | G30: ='Resumen-DiarioHorario-Eólico'!AD130 -> 283.3785 | H30: ='Resumen-DiarioHorario-Eólico'!AD190 -> 209.43283 | I30: ='Resumen-DiarioHorario-Eólico'!AD250 -> 189.54217 | J30: ='Resumen-DiarioHorario-Eólico'!AD310 -> 132.1195 | K30: ='Resumen-DiarioHorario-Eólico'!AD370 -> 153.06 | L30: ='Resumen-DiarioHorario-Eólico'!AD430 -> 213.35217 | M30: ='Resumen-DiarioHorario-Eólico'!AD490 -> 170.5625 | N30: ='Resumen-DiarioHorario-Eólico'!AD550 -> 220.06483 | O30: ='Resumen-DiarioHorario-Eólico'!AD610 -> 214.71567 | P30: ='Resumen-DiarioHorario-Eólico'!AD670 -> 192.5565 | Q30: ='Resumen-DiarioHorario-Eólico'!AD730 -> 247.10667 | R30: ='Resumen-DiarioHorario-Eólico'!AD790 -> 182.41417 | S30: ='Resumen-DiarioHorario-Eólico'!AD850 -> 132.46717 | T30: ='Resumen-DiarioHorario-Eólico'!AD910 -> 127.09483 | U30: ='Resumen-DiarioHorario-Eólico'!AD970 -> 172.805 | V30: ='Resumen-DiarioHorario-Eólico'!AD1030 -> 190.3735 | W30: ='Resumen-DiarioHorario-Eólico'!AD1090 -> 326.25883 | X30: ='Resumen-DiarioHorario-Eólico'!AD1150 -> 84.6295 | Y30: ='Resumen-DiarioHorario-Eólico'!AD1210 -> 43.282833 | Z30: ='Resumen-DiarioHorario-Eólico'!AD1270 -> 178.31717 | AA30: ='Resumen-DiarioHorario-Eólico'!AD1330 -> 348.611 | AB30: ='Resumen-DiarioHorario-Eólico'!AD1390 -> 282.70033 | AC30: ='Resumen-DiarioHorario-Eólico'!AD1450 -> 247.7525 | AD30: ='Resumen-DiarioHorario-Eólico'!AD1510 -> 274.29267 | AE30: ='Resumen-DiarioHorario-Eólico'!AD1570 -> 232.86933 | AF30: ='Resumen-DiarioHorario-Eólico'!AD1629 -> 252.55833 | AG30: ='Resumen-DiarioHorario-Eólico'!AD1688 -> 151.17317 | AH30: =+'Resumen-DiarioHorario-Eólico'!AD1747 -> 183.77667 | AI30: =+'Resumen-DiarioHorario-Eólico'!AD1806 -> 189.4285 | AK30: =SUM(E30:AI30) -> 6269.0695
B31: PE-CERROTIGRE | E31: ='Resumen-DiarioHorario-Eólico'!AD11 -> 250.671 | F31: ='Resumen-DiarioHorario-Eólico'!AD71 -> 357.72517 | G31: ='Resumen-DiarioHorario-Eólico'!AD131 -> 198.36867 | H31: ='Resumen-DiarioHorario-Eólico'!AD191 -> 97.150667 | I31: ='Resumen-DiarioHorario-Eólico'!AD251 -> 192.32383 | J31: ='Resumen-DiarioHorario-Eólico'!AD311 -> 129.59883 | K31: ='Resumen-DiarioHorario-Eólico'!AD371 -> 170.29 | L31: ='Resumen-DiarioHorario-Eólico'!AD431 -> 181.30117 | M31: ='Resumen-DiarioHorario-Eólico'!AD491 -> 179.3395 | N31: ='Resumen-DiarioHorario-Eólico'!AD551 -> 256.27383 | O31: ='Resumen-DiarioHorario-Eólico'!AD611 -> 149.60917 | P31: ='Resumen-DiarioHorario-Eólico'!AD671 -> 67.418167 | Q31: ='Resumen-DiarioHorario-Eólico'!AD731 -> 178.981 | R31: ='Resumen-DiarioHorario-Eólico'!AD791 -> 71.98 | S31: ='Resumen-DiarioHorario-Eólico'!AD851 -> 100.466 | T31: ='Resumen-DiarioHorario-Eólico'!AD911 -> 153.142 | U31: ='Resumen-DiarioHorario-Eólico'!AD971 -> 345.67033 | V31: ='Resumen-DiarioHorario-Eólico'!AD1031 -> 312.15467 | W31: ='Resumen-DiarioHorario-Eólico'!AD1091 -> 282.68483 | X31: ='Resumen-DiarioHorario-Eólico'!AD1151 -> 190.99033 | Y31: ='Resumen-DiarioHorario-Eólico'!AD1211 -> 338.886 | Z31: ='Resumen-DiarioHorario-Eólico'!AD1271 -> 399.94117 | AA31: ='Resumen-DiarioHorario-Eólico'!AD1331 -> 350.294 | AB31: ='Resumen-DiarioHorario-Eólico'!AD1391 -> 191.37183 | AC31: ='Resumen-DiarioHorario-Eólico'!AD1451 -> 195.92483 | AD31: ='Resumen-DiarioHorario-Eólico'!AD1511 -> 251.50367 | AE31: ='Resumen-DiarioHorario-Eólico'!AD1571 -> 276.9495 | AF31: ='Resumen-DiarioHorario-Eólico'!AD1630 -> 336.90333 | AG31: ='Resumen-DiarioHorario-Eólico'!AD1689 -> 257.47667 | AH31: =+'Resumen-DiarioHorario-Eólico'!AD1748 -> 110.8745 | AI31: =+'Resumen-DiarioHorario-Eólico'!AD1807 -> 43.242 | AK31: =SUM(E31:AI31) -> 6619.5067
B32: PE-CALAMA | E32: ='Resumen-DiarioHorario-Eólico'!AD12 -> 171.17717 | F32: ='Resumen-DiarioHorario-Eólico'!AD72 -> 205.847 | G32: ='Resumen-DiarioHorario-Eólico'!AD132 -> 254.942 | H32: ='Resumen-DiarioHorario-Eólico'!AD192 -> 186.09467 | I32: ='Resumen-DiarioHorario-Eólico'!AD252 -> 253.69033 | J32: ='Resumen-DiarioHorario-Eólico'!AD312 -> 165.10117 | K32: ='Resumen-DiarioHorario-Eólico'!AD372 -> 137.43 | L32: ='Resumen-DiarioHorario-Eólico'!AD432 -> 320.0255 | M32: ='Resumen-DiarioHorario-Eólico'!AD492 -> 180.62433 | N32: ='Resumen-DiarioHorario-Eólico'!AD552 -> 277.6915 | O32: ='Resumen-DiarioHorario-Eólico'!AD612 -> 185.00383 | P32: ='Resumen-DiarioHorario-Eólico'!AD672 -> 91.500833 | Q32: ='Resumen-DiarioHorario-Eólico'!AD732 -> 112.77417 | R32: ='Resumen-DiarioHorario-Eólico'!AD792 -> 161.71717 | S32: ='Resumen-DiarioHorario-Eólico'!AD852 -> 182.1535 | T32: ='Resumen-DiarioHorario-Eólico'!AD912 -> 227.52433 | U32: ='Resumen-DiarioHorario-Eólico'!AD972 -> 340.51367 | V32: ='Resumen-DiarioHorario-Eólico'!AD1032 -> 322.41017 | W32: ='Resumen-DiarioHorario-Eólico'!AD1092 -> 305.108 | X32: ='Resumen-DiarioHorario-Eólico'!AD1152 -> 428.58767 | Y32: ='Resumen-DiarioHorario-Eólico'!AD1212 -> 375.33183 | Z32: ='Resumen-DiarioHorario-Eólico'!AD1272 -> 481.0245 | AA32: ='Resumen-DiarioHorario-Eólico'!AD1332 -> 302.79117 | AB32: ='Resumen-DiarioHorario-Eólico'!AD1392 -> 414.65433 | AC32: ='Resumen-DiarioHorario-Eólico'!AD1452 -> 325.49583 | AD32: ='Resumen-DiarioHorario-Eólico'!AD1512 -> 289.226 | AE32: ='Resumen-DiarioHorario-Eólico'!AD1572 -> 210.44033 | AF32: ='Resumen-DiarioHorario-Eólico'!AD1631 -> 296.28417 | AG32: ='Resumen-DiarioHorario-Eólico'!AD1690 -> 224.86567 | AH32: =+'Resumen-DiarioHorario-Eólico'!AD1749 -> 263.66417 | AI32: =+'Resumen-DiarioHorario-Eólico'!AD1808 -> 10.885 | AK32: =SUM(E32:AI32) -> 7704.58
B33: PE-TALTAL | E33: ='Resumen-DiarioHorario-Eólico'!AD13 -> 0 | F33: ='Resumen-DiarioHorario-Eólico'!AD73 -> 0 | G33: ='Resumen-DiarioHorario-Eólico'!AD133 -> 0 | H33: ='Resumen-DiarioHorario-Eólico'!AD193 -> 0 | I33: ='Resumen-DiarioHorario-Eólico'!AD253 -> 0 | J33: ='Resumen-DiarioHorario-Eólico'!AD313 -> 0 | K33: ='Resumen-DiarioHorario-Eólico'!AD373 -> 0 | L33: ='Resumen-DiarioHorario-Eólico'!AD433 -> 162.2747 | M33: ='Resumen-DiarioHorario-Eólico'!AD493 -> 0 | N33: ='Resumen-DiarioHorario-Eólico'!AD553 -> 0 | O33: ='Resumen-DiarioHorario-Eólico'!AD613 -> 0 | P33: ='Resumen-DiarioHorario-Eólico'!AD673 -> 0 | Q33: ='Resumen-DiarioHorario-Eólico'!AD733 -> 0 | R33: ='Resumen-DiarioHorario-Eólico'!AD793 -> 0 | S33: ='Resumen-DiarioHorario-Eólico'!AD853 -> 0 | T33: ='Resumen-DiarioHorario-Eólico'!AD913 -> 0 | U33: ='Resumen-DiarioHorario-Eólico'!AD973 -> 0 | V33: ='Resumen-DiarioHorario-Eólico'!AD1033 -> 0 | W33: ='Resumen-DiarioHorario-Eólico'!AD1093 -> 0 | X33: ='Resumen-DiarioHorario-Eólico'!AD1153 -> 192.476 | Y33: ='Resumen-DiarioHorario-Eólico'!AD1213 -> 0 | Z33: ='Resumen-DiarioHorario-Eólico'!AD1273 -> 0 | AA33: ='Resumen-DiarioHorario-Eólico'!AD1333 -> 0 | AB33: ='Resumen-DiarioHorario-Eólico'!AD1393 -> 0 | AC33: ='Resumen-DiarioHorario-Eólico'!AD1453 -> 0 | AD33: ='Resumen-DiarioHorario-Eólico'!AD1513 -> 0 | AE33: ='Resumen-DiarioHorario-Eólico'!AD1573 -> 0 | AF33: ='Resumen-DiarioHorario-Eólico'!AD1632 -> 0 | AG33: ='Resumen-DiarioHorario-Eólico'!AD1691 -> 0 | AH33: =+'Resumen-DiarioHorario-Eólico'!AD1750 -> 0 | AI33: =+'Resumen-DiarioHorario-Eólico'!AD1809 -> 0 | AK33: =SUM(E33:AI33) -> 354.7507
B34: PE-SARCO | E34: ='Resumen-DiarioHorario-Eólico'!AD14 -> 147.72817 | F34: ='Resumen-DiarioHorario-Eólico'!AD74 -> 59.9665 | G34: ='Resumen-DiarioHorario-Eólico'!AD134 -> 120.406 | H34: ='Resumen-DiarioHorario-Eólico'!AD194 -> 26.239333 | I34: ='Resumen-DiarioHorario-Eólico'!AD254 -> 65.059167 | J34: ='Resumen-DiarioHorario-Eólico'!AD314 -> 25.035833 | K34: ='Resumen-DiarioHorario-Eólico'!AD374 -> 0 | L34: ='Resumen-DiarioHorario-Eólico'!AD434 -> 118.35833 | M34: ='Resumen-DiarioHorario-Eólico'!AD494 -> 39.713833 | N34: ='Resumen-DiarioHorario-Eólico'!AD554 -> 49.455167 | O34: ='Resumen-DiarioHorario-Eólico'!AD614 -> 91.041833 | P34: ='Resumen-DiarioHorario-Eólico'!AD674 -> 55.371167 | Q34: ='Resumen-DiarioHorario-Eólico'!AD734 -> 84.851 | R34: ='Resumen-DiarioHorario-Eólico'!AD794 -> 44.715 | S34: ='Resumen-DiarioHorario-Eólico'!AD854 -> 71.585667 | T34: ='Resumen-DiarioHorario-Eólico'!AD914 -> 99.790833 | U34: ='Resumen-DiarioHorario-Eólico'!AD974 -> 292.15217 | V34: ='Resumen-DiarioHorario-Eólico'!AD1034 -> 89.342333 | W34: ='Resumen-DiarioHorario-Eólico'!AD1094 -> 73.123 | X34: ='Resumen-DiarioHorario-Eólico'!AD1154 -> 138.24217 | Y34: ='Resumen-DiarioHorario-Eólico'!AD1214 -> 73.586333 | Z34: ='Resumen-DiarioHorario-Eólico'!AD1274 -> 129.96483 | AA34: ='Resumen-DiarioHorario-Eólico'!AD1334 -> 98.8435 | AB34: ='Resumen-DiarioHorario-Eólico'!AD1394 -> 85.177667 | AC34: ='Resumen-DiarioHorario-Eólico'!AD1454 -> 56.320167 | AD34: ='Resumen-DiarioHorario-Eólico'!AD1514 -> 53.173833 | AE34: ='Resumen-DiarioHorario-Eólico'!AD1574 -> 35.025667 | AF34: ='Resumen-DiarioHorario-Eólico'!AD1633 -> 57.220333 | AG34: ='Resumen-DiarioHorario-Eólico'!AD1692 -> 262.1005 | AH34: =+'Resumen-DiarioHorario-Eólico'!AD1751 -> 81.5055 | AI34: =+'Resumen-DiarioHorario-Eólico'!AD1810 -> 38.9115 | AK34: =SUM(E34:AI34) -> 2664.0073
B35: PE-CABOLEONES-1 | E35: ='Resumen-DiarioHorario-Eólico'!AD15 -> 51.6765 | F35: ='Resumen-DiarioHorario-Eólico'!AD75 -> 57.426667 | G35: ='Resumen-DiarioHorario-Eólico'!AD135 -> 34.626167 | H35: ='Resumen-DiarioHorario-Eólico'!AD195 -> 57.529 | I35: ='Resumen-DiarioHorario-Eólico'!AD255 -> 28.570333 | J35: ='Resumen-DiarioHorario-Eólico'!AD315 -> 32.46 | K35: ='Resumen-DiarioHorario-Eólico'!AD375 -> 92.07 | L35: ='Resumen-DiarioHorario-Eólico'!AD435 -> 8.0035 | M35: ='Resumen-DiarioHorario-Eólico'!AD495 -> 57.544167 | N35: ='Resumen-DiarioHorario-Eólico'!AD555 -> 21.854 | O35: ='Resumen-DiarioHorario-Eólico'!AD615 -> 55.182833 | P35: ='Resumen-DiarioHorario-Eólico'!AD675 -> 36.140167 | Q35: ='Resumen-DiarioHorario-Eólico'!AD735 -> 60.073333 | R35: ='Resumen-DiarioHorario-Eólico'!AD795 -> 21.553833 | S35: ='Resumen-DiarioHorario-Eólico'!AD855 -> 25.285667 | T35: ='Resumen-DiarioHorario-Eólico'!AD915 -> 0 | U35: ='Resumen-DiarioHorario-Eólico'!AD975 -> 0 | V35: ='Resumen-DiarioHorario-Eólico'!AD1035 -> 0 | W35: ='Resumen-DiarioHorario-Eólico'!AD1095 -> 0 | X35: ='Resumen-DiarioHorario-Eólico'!AD1155 -> 0 | Y35: ='Resumen-DiarioHorario-Eólico'!AD1215 -> 63.383167 | Z35: ='Resumen-DiarioHorario-Eólico'!AD1275 -> 157.70917 | AA35: ='Resumen-DiarioHorario-Eólico'!AD1335 -> 156.27117 | AB35: ='Resumen-DiarioHorario-Eólico'!AD1395 -> 39.622333 | AC35: ='Resumen-DiarioHorario-Eólico'!AD1455 -> 65.762167 | AD35: ='Resumen-DiarioHorario-Eólico'!AD1515 -> 11.7405 | AE35: ='Resumen-DiarioHorario-Eólico'!AD1575 -> 52.969667 | AF35: ='Resumen-DiarioHorario-Eólico'!AD1634 -> 47.234667 | AG35: ='Resumen-DiarioHorario-Eólico'!AD1693 -> 235.04033 | AH35: =+'Resumen-DiarioHorario-Eólico'!AD1752 -> 7.3611667 | AI35: =+'Resumen-DiarioHorario-Eólico'!AD1811 -> 2.1326667 | AK35: =SUM(E35:AI35) -> 1479.2232
B36: PE-CABOLEONES-2 | E36: ='Resumen-DiarioHorario-Eólico'!AD16 -> 1.7696667 | F36: ='Resumen-DiarioHorario-Eólico'!AD76 -> 64.146833 | G36: ='Resumen-DiarioHorario-Eólico'!AD136 -> 52.712333 | H36: ='Resumen-DiarioHorario-Eólico'!AD196 -> 56.874167 | I36: ='Resumen-DiarioHorario-Eólico'!AD256 -> 32.611333 | J36: ='Resumen-DiarioHorario-Eólico'!AD316 -> 34.8325 | K36: ='Resumen-DiarioHorario-Eólico'!AD376 -> 99.37 | L36: ='Resumen-DiarioHorario-Eólico'!AD436 -> 10.075667 | M36: ='Resumen-DiarioHorario-Eólico'!AD496 -> 80.294333 | N36: ='Resumen-DiarioHorario-Eólico'!AD556 -> 58.058833 | O36: ='Resumen-DiarioHorario-Eólico'!AD616 -> 87.316833 | P36: ='Resumen-DiarioHorario-Eólico'!AD676 -> 42.233833 | Q36: ='Resumen-DiarioHorario-Eólico'!AD736 -> 68.9645 | R36: ='Resumen-DiarioHorario-Eólico'!AD796 -> 33.1455 | S36: ='Resumen-DiarioHorario-Eólico'!AD856 -> 27.007333 | T36: ='Resumen-DiarioHorario-Eólico'!AD916 -> 60.369 | U36: ='Resumen-DiarioHorario-Eólico'!AD976 -> 262.0425 | V36: ='Resumen-DiarioHorario-Eólico'!AD1036 -> 13.7595 | W36: ='Resumen-DiarioHorario-Eólico'!AD1096 -> 70.3055 | X36: ='Resumen-DiarioHorario-Eólico'!AD1156 -> 74.522167 | Y36: ='Resumen-DiarioHorario-Eólico'!AD1216 -> 92.889333 | Z36: ='Resumen-DiarioHorario-Eólico'!AD1276 -> 153.113 | AA36: ='Resumen-DiarioHorario-Eólico'!AD1336 -> 24.056833 | AB36: ='Resumen-DiarioHorario-Eólico'!AD1396 -> 6.2315 | AC36: ='Resumen-DiarioHorario-Eólico'!AD1456 -> 3.839 | AD36: ='Resumen-DiarioHorario-Eólico'!AD1516 -> 0 | AE36: ='Resumen-DiarioHorario-Eólico'!AD1576 -> 0 | AF36: ='Resumen-DiarioHorario-Eólico'!AD1635 -> 101.35633 | AG36: ='Resumen-DiarioHorario-Eólico'!AD1694 -> 191.84 | AH36: =+'Resumen-DiarioHorario-Eólico'!AD1753 -> 24.056 | AI36: =+'Resumen-DiarioHorario-Eólico'!AD1812 -> 8.8 | AK36: =SUM(E36:AI36) -> 1836.5943
B37: PE-CABOLEONES-3 | E37: ='Resumen-DiarioHorario-Eólico'!AD17 -> 0.026333333 | F37: ='Resumen-DiarioHorario-Eólico'!AD77 -> 49.534167 | G37: ='Resumen-DiarioHorario-Eólico'!AD137 -> 662.17833 | H37: ='Resumen-DiarioHorario-Eólico'!AD197 -> 75.048333 | I37: ='Resumen-DiarioHorario-Eólico'!AD257 -> 14.1865 | J37: ='Resumen-DiarioHorario-Eólico'!AD317 -> 34.382167 | K37: ='Resumen-DiarioHorario-Eólico'!AD377 -> 71.62 | L37: ='Resumen-DiarioHorario-Eólico'!AD437 -> 8.6413333 | M37: ='Resumen-DiarioHorario-Eólico'!AD497 -> 56.323833 | N37: ='Resumen-DiarioHorario-Eólico'!AD557 -> 26.271667 | O37: ='Resumen-DiarioHorario-Eólico'!AD617 -> 36.46 | P37: ='Resumen-DiarioHorario-Eólico'!AD677 -> 41.898 | Q37: ='Resumen-DiarioHorario-Eólico'!AD737 -> 30.130333 | R37: ='Resumen-DiarioHorario-Eólico'!AD797 -> 0.072666667 | S37: ='Resumen-DiarioHorario-Eólico'!AD857 -> 17.9465 | T37: ='Resumen-DiarioHorario-Eólico'!AD917 -> 0 | U37: ='Resumen-DiarioHorario-Eólico'!AD977 -> 85.276167 | V37: ='Resumen-DiarioHorario-Eólico'!AD1037 -> 0 | W37: ='Resumen-DiarioHorario-Eólico'!AD1097 -> 0 | X37: ='Resumen-DiarioHorario-Eólico'!AD1157 -> 0 | Y37: ='Resumen-DiarioHorario-Eólico'!AD1217 -> 85.106833 | Z37: ='Resumen-DiarioHorario-Eólico'!AD1277 -> 130.725 | AA37: ='Resumen-DiarioHorario-Eólico'!AD1337 -> 160.304 | AB37: ='Resumen-DiarioHorario-Eólico'!AD1397 -> 50.092667 | AC37: ='Resumen-DiarioHorario-Eólico'!AD1457 -> 89.425167 | AD37: ='Resumen-DiarioHorario-Eólico'!AD1517 -> 5.2888333 | AE37: ='Resumen-DiarioHorario-Eólico'!AD1577 -> 45.749833 | AF37: ='Resumen-DiarioHorario-Eólico'!AD1636 -> 48.280333 | AG37: ='Resumen-DiarioHorario-Eólico'!AD1695 -> 189.255 | AH37: =+'Resumen-DiarioHorario-Eólico'!AD1754 -> 10.287167 | AI37: =+'Resumen-DiarioHorario-Eólico'!AD1813 -> 11.975833 | AK37: =SUM(E37:AI37) -> 2036.487
B38: PE-SANJUAN | E38: ='Resumen-DiarioHorario-Eólico'!AD18 -> 317.57567 | F38: ='Resumen-DiarioHorario-Eólico'!AD78 -> 109.4145 | G38: ='Resumen-DiarioHorario-Eólico'!AD138 -> 144.176 | H38: ='Resumen-DiarioHorario-Eólico'!AD198 -> 82.659833 | I38: ='Resumen-DiarioHorario-Eólico'!AD258 -> 53.209 | J38: ='Resumen-DiarioHorario-Eólico'!AD318 -> 81.321833 | K38: ='Resumen-DiarioHorario-Eólico'!AD378 -> 113.19 | L38: ='Resumen-DiarioHorario-Eólico'!AD438 -> 120.09433 | M38: ='Resumen-DiarioHorario-Eólico'!AD498 -> 481.692 | N38: ='Resumen-DiarioHorario-Eólico'!AD558 -> 121.79917 | O38: ='Resumen-DiarioHorario-Eólico'!AD618 -> 508.22983 | P38: ='Resumen-DiarioHorario-Eólico'!AD678 -> 130.19033 | Q38: ='Resumen-DiarioHorario-Eólico'!AD738 -> 192.1365 | R38: ='Resumen-DiarioHorario-Eólico'!AD798 -> 148.47767 | S38: ='Resumen-DiarioHorario-Eólico'!AD858 -> 82.270167 | T38: ='Resumen-DiarioHorario-Eólico'!AD918 -> 138.93833 | U38: ='Resumen-DiarioHorario-Eólico'!AD978 -> 559.778 | V38: ='Resumen-DiarioHorario-Eólico'!AD1038 -> 117.67667 | W38: ='Resumen-DiarioHorario-Eólico'!AD1098 -> 143.10917 | X38: ='Resumen-DiarioHorario-Eólico'!AD1158 -> 186.032 | Y38: ='Resumen-DiarioHorario-Eólico'!AD1218 -> 437.86983 | Z38: ='Resumen-DiarioHorario-Eólico'!AD1278 -> 472.50217 | AA38: ='Resumen-DiarioHorario-Eólico'!AD1338 -> 599.95883 | AB38: ='Resumen-DiarioHorario-Eólico'!AD1398 -> 130.98833 | AC38: ='Resumen-DiarioHorario-Eólico'!AD1458 -> 318.28383 | AD38: ='Resumen-DiarioHorario-Eólico'!AD1518 -> 178.09417 | AE38: ='Resumen-DiarioHorario-Eólico'!AD1578 -> 190.03883 | AF38: ='Resumen-DiarioHorario-Eólico'!AD1637 -> 289.02583 | AG38: ='Resumen-DiarioHorario-Eólico'!AD1696 -> 530.504 | AH38: =+'Resumen-DiarioHorario-Eólico'!AD1755 -> 52.907 | AI38: =+'Resumen-DiarioHorario-Eólico'!AD1814 -> 88.863333 | AK38: =SUM(E38:AI38) -> 7121.0072
B39: PE-PUNTACOLORADA | E39: ='Resumen-DiarioHorario-Eólico'!AD19 -> 0 | F39: ='Resumen-DiarioHorario-Eólico'!AD79 -> 0 | G39: ='Resumen-DiarioHorario-Eólico'!AD139 -> 0 | H39: ='Resumen-DiarioHorario-Eólico'!AD199 -> 0 | I39: ='Resumen-DiarioHorario-Eólico'!AD259 -> 0 | J39: ='Resumen-DiarioHorario-Eólico'!AD319 -> 0 | K39: ='Resumen-DiarioHorario-Eólico'!AD379 -> 0 | L39: ='Resumen-DiarioHorario-Eólico'!AD439 -> 0 | M39: ='Resumen-DiarioHorario-Eólico'!AD499 -> 0 | N39: ='Resumen-DiarioHorario-Eólico'!AD559 -> 0 | O39: ='Resumen-DiarioHorario-Eólico'!AD619 -> 0 | P39: ='Resumen-DiarioHorario-Eólico'!AD679 -> 0 | Q39: ='Resumen-DiarioHorario-Eólico'!AD739 -> 0 | R39: ='Resumen-DiarioHorario-Eólico'!AD799 -> 0 | S39: ='Resumen-DiarioHorario-Eólico'!AD859 -> 0 | T39: ='Resumen-DiarioHorario-Eólico'!AD919 -> 0 | U39: ='Resumen-DiarioHorario-Eólico'!AD979 -> 0 | V39: ='Resumen-DiarioHorario-Eólico'!AD1039 -> 0 | W39: ='Resumen-DiarioHorario-Eólico'!AD1099 -> 0 | X39: ='Resumen-DiarioHorario-Eólico'!AD1159 -> 0 | Y39: ='Resumen-DiarioHorario-Eólico'!AD1219 -> 0 | Z39: ='Resumen-DiarioHorario-Eólico'!AD1279 -> 0 | AA39: ='Resumen-DiarioHorario-Eólico'!AD1339 -> 0 | AB39: ='Resumen-DiarioHorario-Eólico'!AD1399 -> 0 | AC39: ='Resumen-DiarioHorario-Eólico'!AD1459 -> 0 | AD39: ='Resumen-DiarioHorario-Eólico'!AD1519 -> 0 | AE39: ='Resumen-DiarioHorario-Eólico'!AD1579 -> 0 | AF39: ='Resumen-DiarioHorario-Eólico'!AD1638 -> 0 | AG39: ='Resumen-DiarioHorario-Eólico'!AD1697 -> 0 | AH39: =+'Resumen-DiarioHorario-Eólico'!AD1756 -> 0 | AI39: =+'Resumen-DiarioHorario-Eólico'!AD1815 -> 0 | AK39: =SUM(E39:AI39) -> 0
... B72: PE-ATACAMA | E72: ='Resumen-DiarioHorario-Eólico'!AD52 -> 1.1325 | F72: ='Resumen-DiarioHorario-Eólico'!AD112 -> 216.68867 | G72: ='Resumen-DiarioHorario-Eólico'!AD172 -> 454.00633 | H72: ='Resumen-DiarioHorario-Eólico'!AD232 -> 20.7455 | I72: ='Resumen-DiarioHorario-Eólico'!AD292 -> 119.53833 | J72: ='Resumen-DiarioHorario-Eólico'!AD352 -> 41.631167 | K72: ='Resumen-DiarioHorario-Eólico'!AD412 -> 48.55 | L72: ='Resumen-DiarioHorario-Eólico'!AD472 -> 365.46383 | M72: ='Resumen-DiarioHorario-Eólico'!AD532 -> 461.44133 | N72: ='Resumen-DiarioHorario-Eólico'!AD592 -> 41.250167 | O72: ='Resumen-DiarioHorario-Eólico'!AD652 -> 490.51783 | P72: ='Resumen-DiarioHorario-Eólico'!AD712 -> 227.21767 | Q72: ='Resumen-DiarioHorario-Eólico'!AD772 -> 383.6705 | R72: ='Resumen-DiarioHorario-Eólico'!AD832 -> 376.43483 | S72: ='Resumen-DiarioHorario-Eólico'!AD892 -> 153.184 | T72: ='Resumen-DiarioHorario-Eólico'!AD952 -> 106.7815 | U72: ='Resumen-DiarioHorario-Eólico'!AD1012 -> 574.3955 | V72: ='Resumen-DiarioHorario-Eólico'!AD1072 -> 390.39817 | W72: ='Resumen-DiarioHorario-Eólico'!AD1132 -> 633.94217 | X72: ='Resumen-DiarioHorario-Eólico'!AD1192 -> 771.50933 | Y72: ='Resumen-DiarioHorario-Eólico'!AD1252 -> 750.7675 | Z72: ='Resumen-DiarioHorario-Eólico'!AD1312 -> 771.22017 | AA72: ='Resumen-DiarioHorario-Eólico'!AD1372 -> 31.611667 | AB72: ='Resumen-DiarioHorario-Eólico'!AD1432 -> 0 | AC72: ='Resumen-DiarioHorario-Eólico'!AD1492 -> 0 | AD72: ='Resumen-DiarioHorario-Eólico'!AD1552 -> 73.684 | AE72: ='Resumen-DiarioHorario-Eólico'!AD1612 -> 58.084 | AF72: ='Resumen-DiarioHorario-Eólico'!AD1671 -> 647.43833 | AG72: ='Resumen-DiarioHorario-Eólico'!AD1730 -> 561.202 | AH72: =+'Resumen-DiarioHorario-Eólico'!AD1789 -> 244.9495 | AI72: =+'Resumen-DiarioHorario-Eólico'!AD1848 -> 0.8445 | AK72: =SUM(E72:AI72) -> 9018.301
B73: PE-LACABANA | D73: † | E73: ='Resumen-DiarioHorario-Eólico'!AD53 -> 0 | F73: ='Resumen-DiarioHorario-Eólico'!AD113 -> 0 | G73: ='Resumen-DiarioHorario-Eólico'!AD173 -> 0 | H73: ='Resumen-DiarioHorario-Eólico'!AD233 -> 0 | I73: ='Resumen-DiarioHorario-Eólico'!AD293 -> 0 | J73: ='Resumen-DiarioHorario-Eólico'!AD353 -> 0 | K73: ='Resumen-DiarioHorario-Eólico'!AD413 -> 0 | L73: ='Resumen-DiarioHorario-Eólico'!AD473 -> 0 | M73: ='Resumen-DiarioHorario-Eólico'!AD533 -> 0 | N73: ='Resumen-DiarioHorario-Eólico'!AD593 -> 0 | O73: ='Resumen-DiarioHorario-Eólico'!AD653 -> 0 | P73: ='Resumen-DiarioHorario-Eólico'!AD713 -> 0 | Q73: ='Resumen-DiarioHorario-Eólico'!AD773 -> 0 | R73: ='Resumen-DiarioHorario-Eólico'!AD833 -> 0 | S73: ='Resumen-DiarioHorario-Eólico'!AD893 -> 0 | T73: ='Resumen-DiarioHorario-Eólico'!AD953 -> 0 | U73: ='Resumen-DiarioHorario-Eólico'!AD1013 -> 0 | V73: ='Resumen-DiarioHorario-Eólico'!AD1073 -> 0 | W73: ='Resumen-DiarioHorario-Eólico'!AD1133 -> 0 | X73: ='Resumen-DiarioHorario-Eólico'!AD1193 -> 0 | Y73: ='Resumen-DiarioHorario-Eólico'!AD1253 -> 0 | Z73: ='Resumen-DiarioHorario-Eólico'!AD1313 -> 0 | AA73: ='Resumen-DiarioHorario-Eólico'!AD1373 -> 0 | AB73: ='Resumen-DiarioHorario-Eólico'!AD1433 -> 0 | AC73: ='Resumen-DiarioHorario-Eólico'!AD1493 -> 0 | AD73: ='Resumen-DiarioHorario-Eólico'!AD1553 -> 0 | AE73: ='Resumen-DiarioHorario-Eólico'!AD1613 -> 0 | AF73: ='Resumen-DiarioHorario-Eólico'!AD1672 -> 0 | AG73: ='Resumen-DiarioHorario-Eólico'!AD1731 -> 0 | AH73: =+'Resumen-DiarioHorario-Eólico'!AD1790 -> 0 | AI73: =+'Resumen-DiarioHorario-Eólico'!AD1849 -> 0 | AK73: =SUM(E73:AI73) -> 0
B74: PE-SANMATIAS | E74: ='Resumen-DiarioHorario-Eólico'!AD54 -> 81.2985 | F74: ='Resumen-DiarioHorario-Eólico'!AD114 -> 0.29233333 | G74: ='Resumen-DiarioHorario-Eólico'!AD174 -> 50.933 | H74: ='Resumen-DiarioHorario-Eólico'!AD234 -> 143.7085 | I74: ='Resumen-DiarioHorario-Eólico'!AD294 -> 193.82583 | J74: ='Resumen-DiarioHorario-Eólico'!AD354 -> 26.938833 | K74: ='Resumen-DiarioHorario-Eólico'!AD414 -> 32.56 | L74: ='Resumen-DiarioHorario-Eólico'!AD474 -> 60.5255 | M74: ='Resumen-DiarioHorario-Eólico'!AD534 -> 0.12183333 | N74: ='Resumen-DiarioHorario-Eólico'!AD594 -> 2.9743333 | O74: ='Resumen-DiarioHorario-Eólico'!AD654 -> 4.0635 | P74: ='Resumen-DiarioHorario-Eólico'!AD714 -> 75.527667 | Q74: ='Resumen-DiarioHorario-Eólico'!AD774 -> 183.148 | R74: ='Resumen-DiarioHorario-Eólico'!AD834 -> 120.84767 | S74: ='Resumen-DiarioHorario-Eólico'!AD894 -> 92.6465 | T74: ='Resumen-DiarioHorario-Eólico'!AD954 -> 39.684 | U74: ='Resumen-DiarioHorario-Eólico'!AD1014 -> 0 | V74: ='Resumen-DiarioHorario-Eólico'!AD1074 -> 0 | W74: ='Resumen-DiarioHorario-Eólico'!AD1134 -> 0 | X74: ='Resumen-DiarioHorario-Eólico'!AD1194 -> 0 | Y74: ='Resumen-DiarioHorario-Eólico'!AD1254 -> 35.849333 | Z74: ='Resumen-DiarioHorario-Eólico'!AD1314 -> 0.47116667 | AA74: ='Resumen-DiarioHorario-Eólico'!AD1374 -> 0 | AB74: ='Resumen-DiarioHorario-Eólico'!AD1434 -> 0 | AC74: ='Resumen-DiarioHorario-Eólico'!AD1494 -> 15.736667 | AD74: ='Resumen-DiarioHorario-Eólico'!AD1554 -> 0 | AE74: ='Resumen-DiarioHorario-Eólico'!AD1614 -> 0 | AF74: ='Resumen-DiarioHorario-Eólico'!AD1673 -> 13.589833 | AG74: ='Resumen-DiarioHorario-Eólico'!AD1732 -> 0.0091666667 | AH74: =+'Resumen-DiarioHorario-Eólico'!AD1791 -> 0.84066667 | AI74: =+'Resumen-DiarioHorario-Eólico'!AD1850 -> 25.296 | AK74: =SUM(E74:AI74) -> 1200.8888
B75: PE-CARDONAL | E75: ='Resumen-DiarioHorario-Eólico'!AD55 -> 4.837725 | F75: ='Resumen-DiarioHorario-Eólico'!AD115 -> 13.210635 | G75: ='Resumen-DiarioHorario-Eólico'!AD175 -> 22.612432 | H75: ='Resumen-DiarioHorario-Eólico'!AD235 -> 39.35279 | I75: ='Resumen-DiarioHorario-Eólico'!AD295 -> 11.47801 | J75: ='Resumen-DiarioHorario-Eólico'!AD355 -> 4.9791433 | K75: ='Resumen-DiarioHorario-Eólico'!AD415 -> 4.64 | L75: ='Resumen-DiarioHorario-Eólico'!AD475 -> 14.204097 | M75: ='Resumen-DiarioHorario-Eólico'!AD535 -> 0.17018333 | N75: ='Resumen-DiarioHorario-Eólico'!AD595 -> 0.17174333 | O75: ='Resumen-DiarioHorario-Eólico'!AD655 -> 1.0936117 | P75: ='Resumen-DiarioHorario-Eólico'!AD715 -> 49.147108 | Q75: ='Resumen-DiarioHorario-Eólico'!AD775 -> 35.965922 | R75: ='Resumen-DiarioHorario-Eólico'!AD835 -> 15.710598 | S75: ='Resumen-DiarioHorario-Eólico'!AD895 -> 15.675587 | T75: ='Resumen-DiarioHorario-Eólico'!AD955 -> 32.153467 | U75: ='Resumen-DiarioHorario-Eólico'!AD1015 -> 0 | V75: ='Resumen-DiarioHorario-Eólico'!AD1075 -> 0 | W75: ='Resumen-DiarioHorario-Eólico'!AD1135 -> 0 | X75: ='Resumen-DiarioHorario-Eólico'!AD1195 -> 0 | Y75: ='Resumen-DiarioHorario-Eólico'!AD1255 -> 4.9006417 | Z75: ='Resumen-DiarioHorario-Eólico'!AD1315 -> 1.367455 | AA75: ='Resumen-DiarioHorario-Eólico'!AD1375 -> 0 | AB75: ='Resumen-DiarioHorario-Eólico'!AD1435 -> 0 | AC75: ='Resumen-DiarioHorario-Eólico'!AD1495 -> 10.408293 | AD75: ='Resumen-DiarioHorario-Eólico'!AD1555 -> 0 | AE75: ='Resumen-DiarioHorario-Eólico'!AD1615 -> 0 | AF75: ='Resumen-DiarioHorario-Eólico'!AD1674 -> 4.405525 | AG75: ='Resumen-DiarioHorario-Eólico'!AD1733 -> 19.31354 | AH75: =+'Resumen-DiarioHorario-Eólico'!AD1792 -> 0.63793333 | AI75: =+'Resumen-DiarioHorario-Eólico'!AD1851 -> 3.0643217 | AK75: =SUM(E75:AI75) -> 309.50076
B76: PE-CERRILLOS | E76: ='Resumen-DiarioHorario-Eólico'!AD56 -> 13.81524 | F76: ='Resumen-DiarioHorario-Eólico'!AD116 -> 9.1194067 | G76: ='Resumen-DiarioHorario-Eólico'!AD176 -> 21.706293 | H76: ='Resumen-DiarioHorario-Eólico'!AD236 -> 10.219097 | I76: ='Resumen-DiarioHorario-Eólico'!AD296 -> 6.8108533 | J76: ='Resumen-DiarioHorario-Eólico'!AD356 -> 9.9419767 | K76: ='Resumen-DiarioHorario-Eólico'!AD416 -> 10.41 | L76: ='Resumen-DiarioHorario-Eólico'!AD476 -> 12.304197 | M76: ='Resumen-DiarioHorario-Eólico'!AD536 -> 3.6617667 | N76: ='Resumen-DiarioHorario-Eólico'!AD596 -> 0.83396 | O76: ='Resumen-DiarioHorario-Eólico'!AD656 -> 3.6614633 | P76: ='Resumen-DiarioHorario-Eólico'!AD716 -> 50.222967 | Q76: ='Resumen-DiarioHorario-Eólico'!AD776 -> 36.576143 | R76: ='Resumen-DiarioHorario-Eólico'!AD836 -> 22.40496 | S76: ='Resumen-DiarioHorario-Eólico'!AD896 -> 30.639913 | T76: ='Resumen-DiarioHorario-Eólico'!AD956 -> 42.898663 | U76: ='Resumen-DiarioHorario-Eólico'!AD1016 -> 0 | V76: ='Resumen-DiarioHorario-Eólico'!AD1076 -> 0 | W76: ='Resumen-DiarioHorario-Eólico'!AD1136 -> 0 | X76: ='Resumen-DiarioHorario-Eólico'!AD1196 -> 0 | Y76: ='Resumen-DiarioHorario-Eólico'!AD1256 -> 1.5429833 | Z76: ='Resumen-DiarioHorario-Eólico'!AD1316 -> 1.8642633 | AA76: ='Resumen-DiarioHorario-Eólico'!AD1376 -> 0 | AB76: ='Resumen-DiarioHorario-Eólico'!AD1436 -> 0 | AC76: ='Resumen-DiarioHorario-Eólico'!AD1496 -> 5.1954933 | AD76: ='Resumen-DiarioHorario-Eólico'!AD1556 -> 0 | AE76: ='Resumen-DiarioHorario-Eólico'!AD1616 -> 0 | AF76: ='Resumen-DiarioHorario-Eólico'!AD1675 -> 0.40268333 | AG76: ='Resumen-DiarioHorario-Eólico'!AD1734 -> 4.38102 | AH76: =+'Resumen-DiarioHorario-Eólico'!AD1793 -> 3.1722667 | AI76: =+'Resumen-DiarioHorario-Eólico'!AD1852 -> 5.63163 | AK76: =SUM(E76:AI76) -> 307.41724
B77: PE-MANANTIALES | E77: ='Resumen-DiarioHorario-Eólico'!AD57 -> 25.211797 | F77: ='Resumen-DiarioHorario-Eólico'!AD117 -> 21.042 | G77: ='Resumen-DiarioHorario-Eólico'!AD177 -> 25.758737 | H77: ='Resumen-DiarioHorario-Eólico'!AD237 -> 36.7393 | I77: ='Resumen-DiarioHorario-Eólico'!AD297 -> 25.05311 | J77: ='Resumen-DiarioHorario-Eólico'!AD357 -> 23.366388 | K77: ='Resumen-DiarioHorario-Eólico'!AD417 -> 36.99 | L77: ='Resumen-DiarioHorario-Eólico'!AD477 -> 30.299583 | M77: ='Resumen-DiarioHorario-Eólico'!AD537 -> 2.10371 | N77: ='Resumen-DiarioHorario-Eólico'!AD597 -> 0.15659333 | O77: ='Resumen-DiarioHorario-Eólico'!AD657 -> 2.741565 | P77: ='Resumen-DiarioHorario-Eólico'!AD717 -> 66.824862 | Q77: ='Resumen-DiarioHorario-Eólico'!AD777 -> 56.381288 | R77: ='Resumen-DiarioHorario-Eólico'!AD837 -> 39.618113 | S77: ='Resumen-DiarioHorario-Eólico'!AD897 -> 53.694837 | T77: ='Resumen-DiarioHorario-Eólico'!AD957 -> 56.26847 | U77: ='Resumen-DiarioHorario-Eólico'!AD1017 -> 0 | V77: ='Resumen-DiarioHorario-Eólico'!AD1077 -> 0 | W77: ='Resumen-DiarioHorario-Eólico'!AD1137 -> 0 | X77: ='Resumen-DiarioHorario-Eólico'!AD1197 -> 0 | Y77: ='Resumen-DiarioHorario-Eólico'!AD1257 -> 5.2711533 | Z77: ='Resumen-DiarioHorario-Eólico'!AD1317 -> 2.837115 | AA77: ='Resumen-DiarioHorario-Eólico'!AD1377 -> 0 | AB77: ='Resumen-DiarioHorario-Eólico'!AD1437 -> 0 | AC77: ='Resumen-DiarioHorario-Eólico'!AD1497 -> 10.791547 | AD77: ='Resumen-DiarioHorario-Eólico'!AD1557 -> 0 | AE77: ='Resumen-DiarioHorario-Eólico'!AD1617 -> 0 | AF77: ='Resumen-DiarioHorario-Eólico'!AD1676 -> 1.8508833 | AG77: ='Resumen-DiarioHorario-Eólico'!AD1735 -> 7.70052 | AH77: =+'Resumen-DiarioHorario-Eólico'!AD1794 -> 6.75096 | AI77: =+'Resumen-DiarioHorario-Eólico'!AD1853 -> 12.45646 | AK77: =SUM(E77:AI77) -> 549.90899
B78: PE-KALLPA | E78: ='Resumen-DiarioHorario-Eólico'!AD58 -> 438.4815 | F78: ='Resumen-DiarioHorario-Eólico'!AD118 -> 243.72983 | G78: ='Resumen-DiarioHorario-Eólico'!AD178 -> 380.18 | H78: ='Resumen-DiarioHorario-Eólico'!AD238 -> 532.33783 | I78: ='Resumen-DiarioHorario-Eólico'!AD298 -> 363.4725 | J78: ='Resumen-DiarioHorario-Eólico'!AD358 -> 236.46183 | K78: ='Resumen-DiarioHorario-Eólico'!AD418 -> 839.35 | L78: ='Resumen-DiarioHorario-Eólico'!AD478 -> 374.69267 | M78: ='Resumen-DiarioHorario-Eólico'!AD538 -> 82.4385 | N78: ='Resumen-DiarioHorario-Eólico'!AD598 -> 145.15583 | O78: ='Resumen-DiarioHorario-Eólico'!AD658 -> 171.5895 | P78: ='Resumen-DiarioHorario-Eólico'!AD718 -> 286.99833 | Q78: ='Resumen-DiarioHorario-Eólico'!AD778 -> 477.609 | R78: ='Resumen-DiarioHorario-Eólico'!AD838 -> 326.10383 | S78: ='Resumen-DiarioHorario-Eólico'!AD898 -> 612.51843 | T78: ='Resumen-DiarioHorario-Eólico'!AD958 -> 880.67205 | U78: ='Resumen-DiarioHorario-Eólico'!AD1018 -> 0 | V78: ='Resumen-DiarioHorario-Eólico'!AD1078 -> 0 | W78: ='Resumen-DiarioHorario-Eólico'!AD1138 -> 0 | X78: ='Resumen-DiarioHorario-Eólico'!AD1198 -> 0 | Y78: ='Resumen-DiarioHorario-Eólico'!AD1258 -> 417.58883 | Z78: ='Resumen-DiarioHorario-Eólico'!AD1318 -> 15.251667 | AA78: ='Resumen-DiarioHorario-Eólico'!AD1378 -> 572.77067 | AB78: ='Resumen-DiarioHorario-Eólico'!AD1438 -> 0 | AC78: ='Resumen-DiarioHorario-Eólico'!AD1498 -> 113.67617 | AD78: ='Resumen-DiarioHorario-Eólico'!AD1558 -> 0 | AE78: ='Resumen-DiarioHorario-Eólico'!AD1618 -> 0 | AF78: ='Resumen-DiarioHorario-Eólico'!AD1677 -> 484.07117 | AG78: ='Resumen-DiarioHorario-Eólico'!AD1736 -> 598.77533 | AH78: =+'Resumen-DiarioHorario-Eólico'!AD1795 -> 511.3645 | AI78: =+'Resumen-DiarioHorario-Eólico'!AD1854 -> 311.13583 | AK78: =SUM(E78:AI78) -> 9416.4258
B79: PE-HORIZONTENORTE | E79: ='Resumen-DiarioHorario-Eólico'!AD59 -> 126.10433 | F79: ='Resumen-DiarioHorario-Eólico'!AD119 -> 17.4165 | G79: ='Resumen-DiarioHorario-Eólico'!AD179 -> 34.708167 | H79: ='Resumen-DiarioHorario-Eólico'!AD239 -> 91.4082 | I79: ='Resumen-DiarioHorario-Eólico'!AD299 -> 254.8247 | J79: ='Resumen-DiarioHorario-Eólico'!AD359 -> 282.45167 | K79: ='Resumen-DiarioHorario-Eólico'!AD419 -> 540.17 | L79: ='Resumen-DiarioHorario-Eólico'!AD479 -> 1553.2793 | M79: ='Resumen-DiarioHorario-Eólico'!AD539 -> 361.01953 | N79: ='Resumen-DiarioHorario-Eólico'!AD599 -> 368.06962 | O79: ='Resumen-DiarioHorario-Eólico'!AD659 -> 111.88893 | P79: ='Resumen-DiarioHorario-Eólico'!AD719 -> 118.1004 | Q79: ='Resumen-DiarioHorario-Eólico'!AD779 -> 109.66138 | R79: ='Resumen-DiarioHorario-Eólico'!AD839 -> 118.78122 | S79: ='Resumen-DiarioHorario-Eólico'!AD899 -> 475.19317 | T79: ='Resumen-DiarioHorario-Eólico'!AD959 -> 1246.4493 | U79: ='Resumen-DiarioHorario-Eólico'!AD1019 -> 284.37728 | V79: ='Resumen-DiarioHorario-Eólico'!AD1079 -> 171.15917 | W79: ='Resumen-DiarioHorario-Eólico'!AD1139 -> 147.76217 | X79: ='Resumen-DiarioHorario-Eólico'!AD1199 -> 234.00962 | Y79: ='Resumen-DiarioHorario-Eólico'!AD1259 -> 268.7947 | Z79: ='Resumen-DiarioHorario-Eólico'!AD1319 -> 345.43337 | AA79: ='Resumen-DiarioHorario-Eólico'!AD1379 -> 272.98922 | AB79: ='Resumen-DiarioHorario-Eólico'!AD1439 -> 228.5545 | AC79: ='Resumen-DiarioHorario-Eólico'!AD1499 -> 139.572 | AD79: ='Resumen-DiarioHorario-Eólico'!AD1559 -> 173.1105 | AE79: ='Resumen-DiarioHorario-Eólico'!AD1619 -> 154.83417 | AF79: ='Resumen-DiarioHorario-Eólico'!AD1678 -> 150.372 | AG79: ='Resumen-DiarioHorario-Eólico'!AD1737 -> 289.7735 | AH79: =+'Resumen-DiarioHorario-Eólico'!AD1796 -> 528.40883 | AI79: =+'Resumen-DiarioHorario-Eólico'!AD1855 -> 160.03983 | AK79: =SUM(E79:AI79) -> 9358.7173
B80: PE-HORIZONTESUR | E80: ='Resumen-DiarioHorario-Eólico'!AD60 -> 199.20683 | F80: ='Resumen-DiarioHorario-Eólico'!AD120 -> 64.762167 | G80: ='Resumen-DiarioHorario-Eólico'!AD180 -> 94.260167 | H80: ='Resumen-DiarioHorario-Eólico'!AD240 -> 101.66832 | I80: ='Resumen-DiarioHorario-Eólico'!AD300 -> 219.37215 | J80: ='Resumen-DiarioHorario-Eólico'!AD360 -> 273.65618 | K80: ='Resumen-DiarioHorario-Eólico'!AD420 -> 656.76 | L80: ='Resumen-DiarioHorario-Eólico'!AD480 -> 943.71733 | M80: ='Resumen-DiarioHorario-Eólico'!AD540 -> 340.85988 | N80: ='Resumen-DiarioHorario-Eólico'!AD600 -> 315.24877 | O80: ='Resumen-DiarioHorario-Eólico'!AD660 -> 110.58727 | P80: ='Resumen-DiarioHorario-Eólico'!AD720 -> 60.326317 | Q80: ='Resumen-DiarioHorario-Eólico'!AD780 -> 18.39165 | R80: ='Resumen-DiarioHorario-Eólico'!AD840 -> 158.25465 | S80: ='Resumen-DiarioHorario-Eólico'!AD900 -> 483.41667 | T80: ='Resumen-DiarioHorario-Eólico'!AD960 -> 708.47167 | U80: ='Resumen-DiarioHorario-Eólico'!AD1020 -> 217.73845 | V80: ='Resumen-DiarioHorario-Eólico'!AD1080 -> 140.17583 | W80: ='Resumen-DiarioHorario-Eólico'!AD1140 -> 190.91317 | X80: ='Resumen-DiarioHorario-Eólico'!AD1200 -> 1283.5177 | Y80: ='Resumen-DiarioHorario-Eólico'!AD1260 -> 185.12303 | Z80: ='Resumen-DiarioHorario-Eólico'!AD1320 -> 277.11427 | AA80: ='Resumen-DiarioHorario-Eólico'!AD1380 -> 5.4529333 | AB80: ='Resumen-DiarioHorario-Eólico'!AD1440 -> 90.318 | AC80: ='Resumen-DiarioHorario-Eólico'!AD1500 -> 92.884667 | AD80: ='Resumen-DiarioHorario-Eólico'!AD1560 -> 186.20683 | AE80: ='Resumen-DiarioHorario-Eólico'!AD1620 -> 182.09067 | AF80: ='Resumen-DiarioHorario-Eólico'!AD1679 -> 123.13683 | AG80: ='Resumen-DiarioHorario-Eólico'!AD1738 -> 441.22733 | AH80: =+'Resumen-DiarioHorario-Eólico'!AD1797 -> 604.73517 | AI80: =+'Resumen-DiarioHorario-Eólico'!AD1856 -> 279.80317 | AK80: =SUM(E80:AI80) -> 9049.3981
B81: PE-PUNTADETALCA | E81: ='Resumen-DiarioHorario-Eólico'!AD61 -> 18.599667 | F81: ='Resumen-DiarioHorario-Eólico'!AD121 -> 70.0985 | G81: ='Resumen-DiarioHorario-Eólico'!AD181 -> 102.21633 | H81: ='Resumen-DiarioHorario-Eólico'!AD241 -> 121.62083 | I81: ='Resumen-DiarioHorario-Eólico'!AD301 -> 2.8015 | J81: ='Resumen-DiarioHorario-Eólico'!AD361 -> 3.7516667 | K81: ='Resumen-DiarioHorario-Eólico'!AD421 -> 8.27 | L81: ='Resumen-DiarioHorario-Eólico'!AD481 -> 14.875833 | M81: ='Resumen-DiarioHorario-Eólico'!AD541 -> 124.03367 | N81: ='Resumen-DiarioHorario-Eólico'!AD601 -> 55.118667 | O81: ='Resumen-DiarioHorario-Eólico'!AD661 -> 112.21133 | P81: ='Resumen-DiarioHorario-Eólico'!AD721 -> 80.1525 | Q81: ='Resumen-DiarioHorario-Eólico'!AD781 -> 62.459333 | R81: ='Resumen-DiarioHorario-Eólico'!AD841 -> 31.221 | S81: ='Resumen-DiarioHorario-Eólico'!AD901 -> 6.0231667 | T81: ='Resumen-DiarioHorario-Eólico'!AD961 -> 15.404333 | U81: ='Resumen-DiarioHorario-Eólico'!AD1021 -> 270.94483 | V81: ='Resumen-DiarioHorario-Eólico'!AD1081 -> 65.932667 | W81: ='Resumen-DiarioHorario-Eólico'!AD1141 -> 7.6438333 | X81: ='Resumen-DiarioHorario-Eólico'!AD1201 -> 0 | Y81: ='Resumen-DiarioHorario-Eólico'!AD1261 -> 64.028333 | Z81: ='Resumen-DiarioHorario-Eólico'!AD1321 -> 91.680333 | AA81: ='Resumen-DiarioHorario-Eólico'!AD1381 -> 362.755 | AB81: ='Resumen-DiarioHorario-Eólico'!AD1441 -> 149.61267 | AC81: ='Resumen-DiarioHorario-Eólico'!AD1501 -> 171.90233 | AD81: ='Resumen-DiarioHorario-Eólico'!AD1561 -> 30.365333 | AE81: ='Resumen-DiarioHorario-Eólico'!AD1621 -> 29.010833 | AF81: ='Resumen-DiarioHorario-Eólico'!AD1680 -> 121.06783 | AG81: ='Resumen-DiarioHorario-Eólico'!AD1739 -> 86.556833 | AH81: =+'Resumen-DiarioHorario-Eólico'!AD1798 -> 1.2346667 | AI81: =+'Resumen-DiarioHorario-Eólico'!AD1857 -> 2.6411667 | AK81: =SUM(E81:AI81) -> 2284.235
...

Sheet Resumen-DiarioHorario-Eólico
B2: CURTAILMENTS EÓLICAS POR CENTRALES EN FORMA DIARIA/HORARIA
B5: ='Resumen-Mensual'!$E$26 -> 46082
B7: Central/Hora | E7: 1 | F7: 2 | G7: 3 | H7: 4 | I7: 5 | J7: 6 | K7: 7 | L7: 8 | M7: 9 | N7: 10 | O7: 11 | P7: 12 | Q7: 13 | R7: 14 | S7: 15 | T7: 16 | U7: 17 | V7: 18 | W7: 19 | X7: 20 | Y7: 21 | Z7: 22 | AA7: 23 | AB7: 24 | AC7: Total
B8: PE-TCHAMMA | E8: 0 | F8: 0 | G8: 0 | H8: 0 | I8: 0 | J8: 0 | K8: 0 | L8: 0 | M8: 11.385333 | N8: 16.1985 | O8: 8.582 | P8: 7.1731667 | Q8: 12.561167 | R8: 8.0171667 | S8: 1.4533333 | T8: 1.7538333 | U8: 1.468 | V8: 7.4921667 | W8: 19.396 | X8: 11.308333 | Y8: 0 | Z8: 0 | AA8: 0 | AB8: 0 | AD8: =SUM(E8:AB8) -> 106.789
B9: PE-SIERRAGORDA | E9: 0 | F9: 0 | G9: 0 | H9: 0 | I9: 0 | J9: 0 | K9: 0 | L9: 0 | M9: 2.2606667 | N9: 1.2808333 | O9: 4.4693333 | P9: 2.5383333 | Q9: 1.5736667 | R9: 0.69183333 | S9: 0.2415 | T9: 0 | U9: 1.8455 | V9: 4.809 | W9: 23.4045 | X9: 13.207 | Y9: 0 | Z9: 0 | AA9: 0 | AB9: 0 | AD9: =SUM(E9:AB9) -> 56.322167
B10: PE-VALLEDELOSVIENTOS | E10: 0 | F10: 0 | G10: 0 | H10: 0 | I10: 0 | J10: 0 | K10: 0 | L10: 0 | M10: 0.050833333 | N10: 0 | O10: 0.80816667 | P10: 4.065 | Q10: 12.350833 | R10: 12.768167 | S10: 35.023667 | T10: 43.901167 | U10: 45.6 | V10: 45.298667 | W10: 44.136167 | X10: 5.8941667 | Y10: 0 | Z10: 0 | AA10: 0 | AB10: 0 | AD10: =SUM(E10:AB10) -> 249.89683
B11: PE-CERROTIGRE | E11: 0 | F11: 0 | G11: 0 | H11: 0 | I11: 0 | J11: 0 | K11: 0 | L11: 0 | M11: 0.3 | N11: 0.1 | O11: 0 | P11: 2.8 | Q11: 15.409667 | R11: 44.068167 | S11: 16.375833 | T11: 7.9548333 | U11: 15.297833 | V11: 44.566667 | W11: 81.022667 | X11: 22.775333 | Y11: 0 | Z11: 0 | AA11: 0 | AB11: 0 | AD11: =SUM(E11:AB11) -> 250.671
B12: PE-CALAMA | E12: 0 | F12: 0 | G12: 0 | H12: 0 | I12: 0 | J12: 0 | K12: 0 | L12: 0 | M12: 0 | N12: 0 | O12: 0 | P12: 0 | Q12: 0 | R12: 0 | S12: 0 | T12: 23.197333 | U12: 45.910333 | V12: 53.4245 | W12: 44.916833 | X12: 3.7281667 | Y12: 0 | Z12: 0 | AA12: 0 | AB12: 0 | AD12: =SUM(E12:AB12) -> 171.17717
B13: PE-TALTAL | E13: 0 | F13: 0 | G13: 0 | H13: 0 | I13: 0 | J13: 0 | K13: 0 | L13: 0 | M13: 0 | N13: 0 | O13: 0 | P13: 0 | Q13: 0 | R13: 0 | S13: 0 | T13: 0 | U13: 0 | V13: 0 | W13: 0 | X13: 0 | Y13: 0 | Z13: 0 | AA13: 0 | AB13: 0 | AD13: =SUM(E13:AB13) -> 0
B14: PE-SARCO | E14: 0 | F14: 0 | G14: 0 | H14: 0 | I14: 0 | J14: 0 | K14: 0 | L14: 0 | M14: 10.185333 | N14: 9.1436667 | O14: 3.781 | P14: 0.55716667 | Q14: 0.415 | R14: 3.3853333 | S14: 11.450167 | T14: 18.782333 | U14: 33.324 | V14: 15.645833 | W14: 18.408333 | X14: 22.65 | Y14: 0 | Z14: 0 | AA14: 0 | AB14: 0 | AD14: =SUM(E14:AB14) -> 147.72817
B15: PE-CABOLEONES-1 | E15: 0 | F15: 0 | G15: 0 | H15: 0 | I15: 0 | J15: 0 | K15: 0 | L15: 0 | M15: 6.0661667 | N15: 5.2036667 | O15: 2.3253333 | P15: 2.7258333 | Q15: 4.5538333 | R15: 6.8456667 | S15: 4.9528333 | T15: 7.1245 | U15: 0 | V15: 0 | W15: 0 | X15: 11.878667 | Y15: 0 | Z15: 0 | AA15: 0 | AB15: 0 | AD15: =SUM(E15:AB15) -> 51.6765
B16: PE-CABOLEONES-2 | E16: 0 | F16: 0 | G16: 0 | H16: 0 | I16: 0 | J16: 0 | K16: 0 | L16: 0 | M16: 0 | N16: 0 | O16: 0 | P16: 0 | Q16: 0.53283333 | R16: 1.2368333 | S16: 0 | T16: 0 | U16: 0 | V16: 0 | W16: 0 | X16: 0 | Y16: 0 | Z16: 0 | AA16: 0 | AB16: 0 | AD16: =SUM(E16:AB16) -> 1.7696667
B17: PE-CABOLEONES-3 | E17: 0 | F17: 0 | G17: 0 | H17: 0 | I17: 0 | J17: 0 | K17: 0 | L17: 0 | M17: 0.0028333333 | N17: 0 | O17: 0.0025 | P17: 0.015 | Q17: 0.006 | R17: 0 | S17: 0 | T17: 0 | U17: 0 | V17: 0 | W17: 0 | X17: 0 | Y17: 0 | Z17: 0 | AA17: 0 | AB17: 0 | AD17: =SUM(E17:AB17) -> 0.026333333
B18: PE-SANJUAN | E18: 0 | F18: 0 | G18: 0 | H18: 0 | I18: 0 | J18: 0 | K18: 0 | L18: 0 | M18: 9.45 | N18: 10.61 | O18: 10.717833 | P18: 11 | Q18: 11.292333 | R18: 12.906 | S18: 16.239667 | T18: 32.212667 | U18: 60.008667 | V18: 62.278833 | W18: 77.961333 | X18: 2.8983333 | Y18: 0 | Z18: 0 | AA18: 0 | AB18: 0 | AD18: =SUM(E18:AB18) -> 317.57567
B19: PE-PUNTACOLORADA | E19: 0 | F19: 0 | G19: 0 | H19: 0 | I19: 0 | J19: 0 | K19: 0 | L19: 0 | M19: 0 | N19: 0 | O19: 0 | P19: 0 | Q19: 0 | R19: 0 | S19: 0 | T19: 0 | U19: 0 | V19: 0 | W19: 0 | X19: 0 | Y19: 0 | Z19: 0 | AA19: 0 | AB19: 0 | AD19: =SUM(E19:AB19) -> 0
... B61: PE-PUNTADETALCA | E61: 0 | F61: 0 | G61: 0 | H61: 0 | I61: 0 | J61: 0 | K61: 0 | L61: 0 | M61: 3.7006667 | N61: 2.6741667 | O61: 3.74 | P61: 3.3721667 | Q61: 2.3498333 | R61: 0 | S61: 0 | T61: 0.233 | U61: 0.72266667 | V61: 0 | W61: 0.35716667 | X61: 1.45 | Y61: 0 | Z61: 0 | AA61: 0 | AB61: 0 | AD61: =SUM(E61:AB61) -> 18.599667
B62: Total | E62: =SUM(E8:E61) -> 0 | F62: =SUM(F8:F61) -> 0 | G62: =SUM(G8:G61) -> 0 | H62: =SUM(H8:H61) -> 0 | I62: =SUM(I8:I61) -> 0 | J62: =SUM(J8:J61) -> 0 | K62: =SUM(K8:K61) -> 0 | L62: =SUM(L8:L61) -> 0 | ... AB62: =SUM(AB8:AB61) -> 0 | AC62: =SUM(AC8:AE61) -> 4699.0964
B65: ='Resumen-Mensual'!$F$26 -> 46083
B67: Central/Hora | E67: 1 | F67: 2 | G67: 3 | H67: 4 | I67: 5 | J67: 6 | K67: 7 | L67: 8 | M67: 9 | N67: 10 | O67: 11 | P67: 12 | Q67: 13 | R67: 14 | S67: 15 | T67: 16 | U67: 17 | V67: 18 | W67: 19 | X67: 20 | Y67: 21 | Z67: 22 | AA67: 23 | AB67: 24 | AC67: Total
B68: PE-TCHAMMA | E68: 0 | F68: 0 | G68: 0 | H68: 0 | I68: 0 | J68: 0 | K68: 0 | L68: 0 | M68: 4.8541667 | N68: 10.254333 | O68: 8.667 | P68: 8.103 | Q68: 11.285667 | R68: 4.7145 | S68: 9.8903333 | T68: 3.462 | U68: 11.390833 | V68: 20.301 | W68: 22.5865 | X68: 6.4516667 | Y68: 0 | Z68: 0 | AA68: 0 | AB68: 0 | AD68: =SUM(E68:AB68) -> 121.961
B69: PE-SIERRAGORDA | E69: 0 | F69: 0 | G69: 0 | H69: 0 | I69: 0 | J69: 0 | K69: 0 | L69: 0 | M69: 0.94316667 | N69: 2.942 | O69: 6.1 | P69: 5.845 | Q69: 4.668 | R69: 3.8481667 | S69: 9.9228333 | T69: 0 | U69: 0 | V69: 0.12166667 | W69: 13.814667 | X69: 7.4506667 | Y69: 0 | Z69: 0 | AA69: 0 | AB69: 0 | AD69: =SUM(E69:AB69) -> 55.656167
B70: PE-VALLEDELOSVIENTOS | E70: 0 | F70: 0 | G70: 0 | H70: 0 | I70: 0 | J70: 0 | K70: 0 | L70: 0 | M70: 0.4955 | N70: 1.817 | O70: 1.4808333 | P70: 5.65 | Q70: 11.943667 | R70: 11.2135 | S70: 19.793 | T70: 24.100167 | U70: 36.422833 | V70: 37.010167 | W70: 34.7385 | X70: 7.8106667 | Y70: 0 | Z70: 0 | AA70: 0 | AB70: 0 | AD70: =SUM(E70:AB70) -> 192.47583
B71: PE-CERROTIGRE | E71: 0 | F71: 0 | G71: 0 | H71: 0 | I71: 0 | J71: 0 | K71: 0 | L71: 0 | M71: 0.046666667 | N71: 0 | O71: 0.1765 | P71: 2.4408333 | Q71: 14.767833 | R71: 49.4 | S71: 9 | T71: 50.05 | U71: 75.05 | V71: 6.6 | W71: 116.7 | X71: 33.493333 | Y71: 0 | Z71: 0 | AA71: 0 | AB71: 0 | AD71: =SUM(E71:AB71) -> 357.72517
B72: PE-CALAMA | E72: 0 | F72: 0 | G72: 0 | H72: 0 | I72: 0 | J72: 0 | K72: 0 | L72: 0 | M72: 2.9315 | N72: 3.784 | O72: 0.55516667 | P72: 6.2401667 | Q72: 16.255 | R72: 18.591833 | S72: 15.049 | T72: 1.9808333 | U72: 18.193667 | V72: 48.19 | W72: 53.516 | X72: 20.559833 | Y72: 0 | Z72: 0 | AA72: 0 | AB72: 0 | AD72: =SUM(E72:AB72) -> 205.847
B73: PE-TALTAL | E73: 0 | F73: 0 | G73: 0 | H73: 0 | I73: 0 | J73: 0 | K73: 0 | L73: 0 | M73: 0 | N73: 0 | O73: 0 | P73: 0 | Q73: 0 | R73: 0 | S73: 0 | T73: 0 | U73: 0 | V73: 0 | W73: 0 | X73: 0 | Y73: 0 | Z73: 0 | AA73: 0 | AB73: 0 | AD73: =SUM(E73:AB73) -> 0
B74: PE-SARCO | E74: 0 | F74: 0 | G74: 0 | H74: 0 | I74: 0 | J74: 0 | K74: 0 | L74: 0 | M74: 0 | N74: 0.93883333 | O74: 3.8558333 | P74: 1.8431667 | Q74: 3.95 | R74: 7.2523333 | S74: 8.9853333 | T74: 0 | U74: 0 | V74: 0 | W74: 18.773333 | X74: 14.367667 | Y74: 0 | Z74: 0 | AA74: 0 | AB74: 0 | AD74: =SUM(E74:AB74) -> 59.9665
B75: PE-CABOLEONES-1 | E75: 0 | F75: 0 | G75: 0 | H75: 0 | I75: 0 | J75: 0 | K75: 0 | L75: 0 | M75: 0.0845 | N75: 1.5965 | O75: 9.613 | P75: 9.4413333 | Q75: 9.7278333 | R75: 12.921333 | S75: 6.518 | T75: 1.915 | U75: 0 | V75: 0 | W75: 1.1903333 | X75: 4.4188333 | Y75: 0 | Z75: 0 | AA75: 0 | AB75: 0 | AD75: =SUM(E75:AB75) -> 57.426667
B76: PE-CABOLEONES-2 | E76: 0 | F76: 0 | G76: 0 | H76: 0 | I76: 0 | J76: 0 | K76: 0 | L76: 0 | M76: 0.0081666667 | N76: 7.9143333 | O76: 9.0998333 | P76: 4.7475 | Q76: 6.615 | R76: 11.501667 | S76: 9.768 | T76: 0.080666667 | U76: 0 | V76: 0 | W76: 10.149167 | X76: 4.2625 | Y76: 0 | Z76: 0 | AA76: 0 | AB76: 0 | AD76: =SUM(E76:AB76) -> 64.146833
B77: PE-CABOLEONES-3 | E77: 0 | F77: 0 | G77: 0 | H77: 0 | I77: 0 | J77: 0 | K77: 0 | L77: 0 | M77: 0.031166667 | N77: 0.0055 | O77: 3.793 | P77: 1.4611667 | Q77: 4.185 | R77: 8.5235 | S77: 6.877 | T77: 0.016666667 | U77: 0 | V77: 0.68433333 | W77: 16.369167 | X77: 7.5876667 | Y77: 0 | Z77: 0 | AA77: 0 | AB77: 0 | AD77: =SUM(E77:AB77) -> 49.534167
B78: PE-SANJUAN | E78: 0 | F78: 0 | G78: 0 | H78: 0 | I78: 0 | J78: 0 | K78: 0 | L78: 0 | M78: 0 | N78: 0.183 | O78: 11.1615 | P78: 10.072833 | Q78: 9.9713333 | R78: 21.7725 | S78: 20.235167 | T78: 5.3513333 | U78: 2.9491667 | V78: 22.0455 | W78: 3.3406667 | X78: 2.3315 | Y78: 0 | Z78: 0 | AA78: 0 | AB78: 0 | AD78: =SUM(E78:AB78) -> 109.4145
B79: PE-PUNTACOLORADA | E79: 0 | F79: 0 | G79: 0 | H79: 0 | I79: 0 | J79: 0 | K79: 0 | L79: 0 | M79: 0 | N79: 0 | O79: 0 | P79: 0 | Q79: 0 | R79: 0 | S79: 0 | T79: 0 | U79: 0 | V79: 0 | W79: 0 | X79: 0 | Y79: 0 | Z79: 0 | AA79: 0 | AB79: 0 | AD79: =SUM(E79:AB79) -> 0
... B121: PE-PUNTADETALCA | E121: 0 | F121: 0 | G121: 0 | H121: 0 | I121: 0 | J121: 0 | K121: 0 | L121: 0 | M121: 0 | N121: 0 | O121: 0 | P121: 0 | Q121: 0 | R121: 0 | S121: 0 | T121: 0 | U121: 0 | V121: 0 | W121: 54.9355 | X121: 15.163 | Y121: 0 | Z121: 0 | AA121: 0 | AB121: 0 | AD121: =SUM(E121:AB121) -> 70.0985
B122: Total | E122: =SUM(E68:E121) -> 0 | F122: =SUM(F68:F121) -> 0 | G122: =SUM(G68:G121) -> 0 | H122: =SUM(H68:H121) -> 0 | I122: =SUM(I68:I121) -> 0 | J122: =SUM(J68:J121) -> 0 | K122: =SUM(K68:K121) -> 0 | L122: =SUM(L68:L121) -> 0 | ... AB122: =SUM(AB68:AB121) -> 0 | AC122: =SUM(AC68:AE121) -> 3036.5574
B125: ='Resumen-Mensual'!$G$26 -> 46084
B127: Central/Hora | E127: 1 | F127: 2 | G127: 3 | H127: 4 | I127: 5 | J127: 6 | K127: 7 | L127: 8 | M127: 9 | N127: 10 | O127: 11 | P127: 12 | Q127: 13 | R127: 14 | S127: 15 | T127: 16 | U127: 17 | V127: 18 | W127: 19 | X127: 20 | Y127: 21 | Z127: 22 | AA127: 23 | AB127: 24 | AC127: Total
B128: PE-TCHAMMA | E128: 0 | F128: 0 | G128: 0 | H128: 0 | I128: 0 | J128: 0 | K128: 0 | L128: 0 | M128: 19.1815 | N128: 9.6355 | O128: 14.128667 | P128: 11.436833 | Q128: 11.456 | R128: 14.354333 | S128: 20.614 | T128: 6.6526667 | U128: 10.105 | V128: 10.1595 | W128: 15.243 | X128: 2.6601667 | Y128: 0 | Z128: 0 | AA128: 0 | AB128: 0 | AD128: =SUM(E128:AB128) -> 145.62717
B129: PE-SIERRAGORDA | E129: 0 | F129: 0 | G129: 0 | H129: 0 | I129: 0 | J129: 0 | K129: 0 | L129: 0 | M129: 0 | N129: 1.6913333 | O129: 4.9685 | P129: 4.943 | Q129: 1.3635 | R129: 7.0876667 | S129: 11.519333 | T129: 0 | U129: 0 | V129: 1.9316667 | W129: 2.1796667 | X129: 5.6936667 | Y129: 0 | Z129: 0 | AA129: 0 | AB129: 0 | AD129: =SUM(E129:AB129) -> 41.378333
B130: PE-VALLEDELOSVIENTOS | E130: 0 | F130: 0 | G130: 0 | H130: 0 | I130: 0 | J130: 0 | K130: 0 | L130: 0 | M130: 1.5456667 | N130: 0.036166667 | O130: 0.675 | P130: 4.1086667 | Q130: 15.169667 | R130: 39.68 | S130: 55.719 | T130: 28.0355 | U130: 34.367833 | V130: 41.5135 | W130: 46.871 | X130: 15.6565 | Y130: 0 | Z130: 0 | AA130: 0 | AB130: 0 | AD130: =SUM(E130:AB130) -> 283.3785
B131: PE-CERROTIGRE | E131: 0 | F131: 0 | G131: 0 | H131: 0 | I131: 0 | J131: 0 | K131: 0 | L131: 0 | M131: 0 | N131: 0 | O131: 0 | P131: 0 | Q131: 10.5 | R131: 28.634167 | S131: 19.567 | T131: 14.312667 | U131: 27.9265 | V131: 39.087833 | W131: 51.249333 | X131: 7.0911667 | Y131: 0 | Z131: 0 | AA131: 0 | AB131: 0 | AD131: =SUM(E131:AB131) -> 198.36867
B132: PE-CALAMA | E132: 0 | F132: 0 | G132: 0 | H132: 0 | I132: 0 | J132: 0 | K132: 0 | L132: 0 | M132: 0 | N132: 0.045333333 | O132: 0.86283333 | P132: 6.1123333 | Q132: 19.115833 | R132: 56.347833 | S132: 60.234833 | T132: 17.687333 | U132: 34.2495 | V132: 50.591167 | W132: 9.695 | X132: 0 | Y132: 0 | Z132: 0 | AA132: 0 | AB132: 0 | AD132: =SUM(E132:AB132) -> 254.942
...

Sheet Resumen-DiarioHorario-Solar
B2: CURTAILMENTS SOLAR POR CENTRALES EN FORMA DIARIA/HORARIA
B5: ='Resumen-Mensual'!$E$26 -> 46082
B7: Central/Hora | E7: 1 | F7: 2 | G7: 3 | H7: 4 | I7: 5 | J7: 6 | K7: 7 | L7: 8 | M7: 9 | N7: 10 | O7: 11 | P7: 12 | Q7: 13 | R7: 14 | S7: 15 | T7: 16 | U7: 17 | V7: 18 | W7: 19 | X7: 20 | Y7: 21 | Z7: 22 | AA7: 23 | AB7: 24 | AC7: Total
B8: PFV-POZOALMONTE-2 | E8: 0 | F8: 0 | G8: 0 | H8: 0 | I8: 0 | J8: 0 | K8: 0 | L8: 0.053333333 | M8: 1.9 | N8: 0 | O8: 0 | P8: 0 | Q8: 0 | R8: 0 | S8: 0 | T8: 0 | U8: 0 | V8: 0 | W8: 0 | X8: 0.32 | Y8: 0 | Z8: 0 | AA8: 0 | AB8: 0 | AD8: =SUM(E8:AB8) -> 2.2733333
B9: PFV-POZOALMONTE-3 | E9: 0 | F9: 0 | G9: 0 | H9: 0 | I9: 0 | J9: 0 | K9: 0 | L9: 0.053333333 | M9: 5.9 | N9: 11.6 | O9: 12.5 | P9: 12.6 | Q9: 12.6 | R9: 12.6 | S9: 12.6 | T9: 12.6 | U9: 12.6 | V9: 12.1 | W9: 7.5 | X9: 0.4 | Y9: 0 | Z9: 0 | AA9: 0 | AB9: 0 | AD9: =SUM(E9:AB9) -> 125.65333
B10: PFV-LAHUAYCA-2 | E10: 0 | F10: 0 | G10: 0 | H10: 0 | I10: 0 | J10: 0 | K10: 0 | L10: 0 | M10: 0.99216667 | N10: 3.0843333 | O10: 5.334 | P10: 8.4175 | Q10: 8.9745 | R10: 7.477 | S10: 6.0683333 | T10: 5.6688333 | U10: 6.3895 | V10: 4.9773333 | W10: 1.4243333 | X10: 0.075 | Y10: 0 | Z10: 0 | AA10: 0 | AB10: 0 | AD10: =SUM(E10:AB10) -> 58.882833
B11: PFV-SANTAISABEL | E11: 0 | F11: 0 | G11: 0 | H11: 0 | I11: 0 | J11: 0 | K11: 0 | L11: 0.36433333 | M11: 59.6915 | N11: 116.24517 | O11: 117.82483 | P11: 107.572 | Q11: 99.619 | R11: 95.432667 | S11: 87.448833 | T11: 84.035167 | U11: 83.603333 | V11: 86.024167 | W11: 50.116333 | X11: 0 | Y11: 0 | Z11: 0 | AA11: 0 | AB11: 0 | AD11: =SUM(E11:AB11) -> 987.97733
B12: PFV-HUATACONDO | E12: 0 | F12: 0 | G12: 0 | H12: 0 | I12: 0 | J12: 0 | K12: 0 | L12: 0 | M12: 0 | N12: 0 | O12: 0 | P12: 0 | Q12: 0 | R12: 0 | S12: 0 | T12: 0 | U12: 0 | V12: 0 | W12: 0 | X12: 0 | Y12: 0 | Z12: 0 | AA12: 0 | AB12: 0 | AD12: =SUM(E12:AB12) -> 0
B13: PFV-ATACAMASOLAR-2 | E13: 0 | F13: 0 | G13: 0 | H13: 0 | I13: 0 | J13: 0 | K13: 0 | L13: 0.037333333 | M13: 5.3976667 | N13: 24.826 | O13: 17.9645 | P13: 15.616167 | Q13: 13.751 | R13: 13.179167 | S13: 12.425833 | T13: 13.599333 | U13: 16.353333 | V13: 18.380333 | W13: 21.346833 | X13: 8.8753333 | Y13: 0 | Z13: 0 | AA13: 0 | AB13: 0 | AD13: =SUM(E13:AB13) -> 181.75283
B14: PFV-NUEVOQUILLAGUA | E14: 0 | F14: 0 | G14: 0 | H14: 0 | I14: 0 | J14: 0 | K14: 0 | L14: 0 | M14: 0 | N14: 0 | O14: 0 | P14: 0 | Q14: 0 | R14: 0 | S14: 0 | T14: 0 | U14: 0 | V14: 0 | W14: 0 | X14: 0 | Y14: 0 | Z14: 0 | AA14: 0 | AB14: 0 | AD14: =SUM(E14:AB14) -> 0
B15: PFV-GRANJA | E15: 0 | F15: 0 | G15: 0 | H15: 0 | I15: 0 | J15: 0 | K15: 0 | L15: 0 | M15: 8.4333333 | N15: 44.255333 | O15: 49.462833 | P15: 43.139167 | Q15: 32.271667 | R15: 25.908167 | S15: 22.592333 | T15: 26.559667 | U15: 41.197 | V15: 49.133833 | W15: 45.788333 | X15: 0 | Y15: 0 | Z15: 0 | AA15: 0 | AB15: 0 | AD15: =SUM(E15:AB15) -> 388.74167
