Workbook

Sheet Resumen-Mensual
B2: RESUMEN DE CURTAILMENTS ACUMULADO DE CENTRALES EÓLICAS, SOLARES HIDRÁULICAS DE PASADA, EMBALSES Y SERIES HÍDRICAS AÑO 2026
C4: Resumen Anual / Mensual (GWh)
C6: Acumulado 2026
B7: Eólica | C7: =SUM(C14,F14,I14,L14,O14,R14,U14,X14,AA14,AD14,AG14,AJ14) -> 195.22041 | E7: =IF($C$11=0,"-",+C7/$C$11) -> 0.24841999
B8: Solar | C8: =SUM(C15,F15,I15,L15,O15,R15,U15,X15,AA15,AD15,AG15,AJ15) -> 581.15774 | E8: =IF($C$11=0,"-",+C8/$C$11) -> 0.73952923 | Y8: =+AJ87/1000-X15 -> 581.15774
B9: Hidro Pasada | C9: =SUM(C16,F16,I16,L16,O16,R16,U16,X16,AA16,AD16,AG16,AJ16) -> 9.3467424 | E9: =IF($C$11=0,"-",+C9/$C$11) -> 0.011893826
B10: Hidro Embalse | C10: =SUM(C17,F17,I17,L17,O17,R17,U17,X17,AA17,AD17,AG17,AJ17) -> 0.12334647 | E10: =IF($C$11=0,"-",+C10/$C$11) -> 0.00015695966
B11: Total | C11: =SUM(C7:C10) -> 785.84824 | E11: =SUM(E7:E10) -> 1
C13: 46023 | F13: 46054 | I13: 46082 | L13: 46113 | O13: 46143 | R13: 46174 | U13: 46204 | X13: 46235 | AA13: 46266 | AD13: 46296 | AG13: 46327 | AJ13: 46357
B14: Eólica | C14: ='Acumulado-Anual-Eólico'!AJ10/1000 -> 195.22041 | E14: =IF($C$18=0,"-",+C14/$C$18) -> 0.24841999 | H14: =IF($F$18=0,"-",+F14/$F$18) -> - | K14: =IF($I$18=0,"-",+I14/$I$18) -> - | N14: =IF($L$18=0,"-",+L14/$L$18) -> - | Q14: =IF($O$18=0,"-",+O14/$O$18) -> - | T14: =IF($R$18=0,"-",+R14/$R$18) -> - | W14: =IF($U$18=0,"-",+U14/$U$18) -> - | Z14: =IF($X$18=0,"-",+X14/$X$18) -> - | AC14: =IF($AA$18=0,"-",+AA14/$AA$18) -> - | AF14: =IF($AD$18=0,"-",+AD14/$AD$18) -> - | AI14: =IF($AG$18=0,"-",+AG14/$AG$18) -> - | AL14: =IF($AJ$18=0,"-",+AJ14/$AJ$18) -> -
B15: Solar | C15: ='Acumulado-Anual-Solar'!AJ10/1000 -> 581.15774 | E15: =IF($C$18=0,"-",+C15/$C$18) -> 0.73952923 | H15: =IF($F$18=0,"-",+F15/$F$18) -> - | K15: =IF($I$18=0,"-",+I15/$I$18) -> - | N15: =IF($L$18=0,"-",+L15/$L$18) -> - | Q15: =IF($O$18=0,"-",+O15/$O$18) -> - | T15: =IF($R$18=0,"-",+R15/$R$18) -> - | W15: =IF($U$18=0,"-",+U15/$U$18) -> - | Z15: =IF($X$18=0,"-",+X15/$X$18) -> - | AC15: =IF($AA$18=0,"-",+AA15/$AA$18) -> - | AF15: =IF($AD$18=0,"-",+AD15/$AD$18) -> - | AI15: =IF($AG$18=0,"-",+AG15/$AG$18) -> - | AL15: =IF($AJ$18=0,"-",+AJ15/$AJ$18) -> -
B16: Hidro Pasada | C16: =+'Acumulado-Anual-HP'!AJ11/1000 -> 9.3467424 | E16: =IF($C$18=0,"-",+C16/$C$18) -> 0.011893826 | H16: =IF($F$18=0,"-",+F16/$F$18) -> - | K16: =IF($I$18=0,"-",+I16/$I$18) -> - | N16: =IF($L$18=0,"-",+L16/$L$18) -> - | Q16: =IF($O$18=0,"-",+O16/$O$18) -> - | T16: =IF($R$18=0,"-",+R16/$R$18) -> - | W16: =IF($U$18=0,"-",+U16/$U$18) -> - | Z16: =IF($X$18=0,"-",+X16/$X$18) -> - | AC16: =IF($AA$18=0,"-",+AA16/$AA$18) -> - | AF16: =IF($AD$18=0,"-",+AD16/$AD$18) -> - | AI16: =IF($AG$18=0,"-",+AG16/$AG$18) -> - | AL16: =IF($AJ$18=0,"-",+AJ16/$AJ$18) -> -
B17: Hidro Embalse | C17: ='Acumulado-Anual-HE'!AJ10/1000 -> 0.12334647 | E17: =IF($C$18=0,"-",+C17/$C$18) -> 0.00015695966 | H17: =IF($F$18=0,"-",+F17/$F$18) -> - | K17: =IF($I$18=0,"-",+I17/$I$18) -> - | N17: =IF($L$18=0,"-",+L17/$L$18) -> - | Q17: =IF($O$18=0,"-",+O17/$O$18) -> - | T17: =IF($R$18=0,"-",+R17/$R$18) -> - | W17: =IF($U$18=0,"-",+U17/$U$18) -> - | Z17: =IF($X$18=0,"-",+X17/$X$18) -> - | AC17: =IF($AA$18=0,"-",+AA17/$AA$18) -> - | AF17: =IF($AD$18=0,"-",+AD17/$AD$18) -> - | AI17: =IF($AG$18=0,"-",+AG17/$AG$18) -> - | AL17: =IF($AJ$18=0,"-",+AJ17/$AJ$18) -> -
B18: Total | C18: =SUM(C14:D17) -> 785.84824 | E18: =SUM(E14:E17) -> 1 | F18: =SUM(F14:G17) -> 0 | H18: =SUM(H14:H17) -> 0 | I18: =SUM(I14:I17) -> 0 | K18: =SUM(K14:K17) -> 0 | L18: =SUM(L14:L17) -> 0 | N18: =SUM(N14:N17) -> 0 | O18: =SUM(O14:O17) -> 0 | Q18: =SUM(Q14:Q17) -> 0 | R18: =SUM(R14:R17) -> 0 | T18: =SUM(T14:T17) -> 0 | U18: =SUM(U14:U17) -> 0 | W18: =SUM(W14:W17) -> 0 | X18: =SUM(X14:X17) -> 0 | Z18: =SUM(Z14:Z17) -> 0 | AA18: =SUM(AA14:AA17) -> 0 | AC18: =SUM(AC14:AC17) -> 0 | AD18: =SUM(AD14:AD17) -> 0 | AF18: =SUM(AF14:AF17) -> 0 | AG18: =SUM(AG14:AG17) -> 0 | AI18: =SUM(AI14:AI17) -> 0 | AJ18: =SUM(AJ14:AJ17) -> 0 | AL18: =SUM(AL14:AL17) -> 0
B21: RESUMEN DE CURTAILMENTS CENTRALES EÓLICAS, SOLARES, HIDRÁULICAS DE PASADA, EMBALSES Y SERIES HÍDRICAS CORRESPONDIENTE A ENERO 2026 (MWh)
B24: DESGLOSE DIARIO DE CURTAILMENTS DE ENERGÍA EÓLICA
B26: Central / Día | E26: 46023 | F26: =+E26+1 -> 46024 | G26: =+F26+1 -> 46025 | H26: =+G26+1 -> 46026 | I26: =+H26+1 -> 46027 | J26: =+I26+1 -> 46028 | K26: =+J26+1 -> 46029 | L26: =+K26+1 -> 46030 | M26: =+L26+1 -> 46031 | ... AI26: =+AH26+1 -> 46053 | AJ26: Total
B27: Total | E27: =SUM(E28:E81) -> 10434.53 | F27: =SUM(F28:F81) -> 8132.6799 | G27: =SUM(G28:G81) -> 5725.9369 | H27: =SUM(H28:H81) -> 5484.4431 | I27: =SUM(I28:I81) -> 3500.2168 | J27: =SUM(J28:J81) -> 7255.3886 | K27: =SUM(K28:K81) -> 6206.4915 | L27: =SUM(L28:L81) -> 4814.2498 | ... AI27: =SUM(AI28:AI81) -> 5670.5899 | AK27: =SUM(AK28:AK81) -> 195220.41
B28: PE-TCHAMMA | E28: ='Resumen-DiarioHorario-Eólico'!AD8 -> 385.72833 | F28: ='Resumen-DiarioHorario-Eólico'!AD68 -> 223.06567 | G28: ='Resumen-DiarioHorario-Eólico'!AD128 -> 217.9165 | H28: ='Resumen-DiarioHorario-Eólico'!AD188 -> 245.51033 | I28: ='Resumen-DiarioHorario-Eólico'!AD248 -> 246.02733 | J28: ='Resumen-DiarioHorario-Eólico'!AD308 -> 377.66217 | K28: ='Resumen-DiarioHorario-Eólico'!AD368 -> 321.92283 | L28: ='Resumen-DiarioHorario-Eólico'!AD428 -> 310.352 | M28: ='Resumen-DiarioHorario-Eólico'!AD488 -> 382.39967 | N28: ='Resumen-DiarioHorario-Eólico'!AD548 -> 390.10383 | O28: ='Resumen-DiarioHorario-Eólico'!AD608 -> 340.7805 | P28: ='Resumen-DiarioHorario-Eólico'!AD668 -> 332.28217 | Q28: ='Resumen-DiarioHorario-Eólico'!AD728 -> 260.031 | R28: ='Resumen-DiarioHorario-Eólico'!AD788 -> 318.8325 | S28: ='Resumen-DiarioHorario-Eólico'!AD848 -> 284.256 | T28: ='Resumen-DiarioHorario-Eólico'!AD908 -> 201.35433 | U28: ='Resumen-DiarioHorario-Eólico'!AD968 -> 324.19017 | V28: ='Resumen-DiarioHorario-Eólico'!AD1028 -> 241.36683 | W28: ='Resumen-DiarioHorario-Eólico'!AD1088 -> 127.01783 | X28: ='Resumen-DiarioHorario-Eólico'!AD1148 -> 335.20133 | Y28: ='Resumen-DiarioHorario-Eólico'!AD1208 -> 423.019 | Z28: ='Resumen-DiarioHorario-Eólico'!AD1268 -> 371.966 | AA28: ='Resumen-DiarioHorario-Eólico'!AD1328 -> 347.32667 | AB28: ='Resumen-DiarioHorario-Eólico'!AD1388 -> 356.29483 | AC28: ='Resumen-DiarioHorario-Eólico'!AD1448 -> 405.1165 | AD28: ='Resumen-DiarioHorario-Eólico'!AD1508 -> 277.713 | AE28: ='Resumen-DiarioHorario-Eólico'!AD1568 -> 367.21917 | AF28: ='Resumen-DiarioHorario-Eólico'!AD1627 -> 114.162 | AG28: ='Resumen-DiarioHorario-Eólico'!AD1686 -> 87.5335 | AH28: =+'Resumen-DiarioHorario-Eólico'!AD1745 -> 291.2815 | AI28: =+'Resumen-DiarioHorario-Eólico'!AD1804 -> 228.60133 | AK28: =SUM(E28:AI28) -> 9136.2348
B29: PE-SIERRAGORDA | E29: ='Resumen-DiarioHorario-Eólico'!AD9 -> 312.77983 | F29: ='Resumen-DiarioHorario-Eólico'!AD69 -> 168.153 | G29: ='Resumen-DiarioHorario-Eólico'!AD129 -> 230.18117 | H29: ='Resumen-DiarioHorario-Eólico'!AD189 -> 299.283 | I29: ='Resumen-DiarioHorario-Eólico'!AD249 -> 150.13183 | J29: ='Resumen-DiarioHorario-Eólico'!AD309 -> 161.56 | K29: ='Resumen-DiarioHorario-Eólico'!AD369 -> 151.93833 | L29: ='Resumen-DiarioHorario-Eólico'!AD429 -> 114.37833 | M29: ='Resumen-DiarioHorario-Eólico'!AD489 -> 171.6095 | N29: ='Resumen-DiarioHorario-Eólico'!AD549 -> 169.12067 | O29: ='Resumen-DiarioHorario-Eólico'!AD609 -> 236.05783 | P29: ='Resumen-DiarioHorario-Eólico'!AD669 -> 241.68267 | Q29: ='Resumen-DiarioHorario-Eólico'!AD729 -> 136.44483 | R29: ='Resumen-DiarioHorario-Eólico'!AD789 -> 155.11417 | S29: ='Resumen-DiarioHorario-Eólico'!AD849 -> 285.17667 | T29: ='Resumen-DiarioHorario-Eólico'!AD909 -> 253.8535 | U29: ='Resumen-DiarioHorario-Eólico'!AD969 -> 298.26267 | V29: ='Resumen-DiarioHorario-Eólico'!AD1029 -> 256.5015 | W29: ='Resumen-DiarioHorario-Eólico'!AD1089 -> 188.76583 | X29: ='Resumen-DiarioHorario-Eólico'!AD1149 -> 207.17817 | Y29: ='Resumen-DiarioHorario-Eólico'!AD1209 -> 221.253 | Z29: ='Resumen-DiarioHorario-Eólico'!AD1269 -> 89.665 | AA29: ='Resumen-DiarioHorario-Eólico'!AD1329 -> 113.8555 | AB29: ='Resumen-DiarioHorario-Eólico'!AD1389 -> 199.5635 | AC29: ='Resumen-DiarioHorario-Eólico'!AD1449 -> 145.73483 | AD29: ='Resumen-DiarioHorario-Eólico'!AD1509 -> 114.843 | AE29: ='Resumen-DiarioHorario-Eólico'!AD1569 -> 156.026 | AF29: ='Resumen-DiarioHorario-Eólico'!AD1628 -> 239.00217 | AG29: ='Resumen-DiarioHorario-Eólico'!AD1687 -> 149.94633 | AH29: =+'Resumen-DiarioHorario-Eólico'!AD1746 -> 273.8255 | AI29: =+'Resumen-DiarioHorario-Eólico'!AD1805 -> 217.93933 | AK29: =SUM(E29:AI29) -> 6109.8277
B30: PE-VALLEDELOSVIENTOS | E30: ='Resumen-DiarioHorario-Eólico'!AD10 -> 301.2645 | F30: ='Resumen-DiarioHorario-Eólico'!AD70 -> 274.9635 | G30: ='Resumen-DiarioHorario-Eólico'!AD130 -> 447.19917 | H30: ='Resumen-DiarioHorario-Eólico'!AD190 -> 268.38667 | I30: ='Resumen-DiarioHorario-Eólico'!AD250 -> 277.57767 | J30: ='Resumen-DiarioHorario-Eólico'!AD310 -> 333.91283 | K30: ='Resumen-DiarioHorario-Eólico'!AD370 -> 226.34917 | L30: ='Resumen-DiarioHorario-Eólico'!AD430 -> 378.36667 | M30: ='Resumen-DiarioHorario-Eólico'!AD490 -> 292.4805 | N30: ='Resumen-DiarioHorario-Eólico'!AD550 -> 365.89433 | O30: ='Resumen-DiarioHorario-Eólico'!AD610 -> 299.75333 | P30: ='Resumen-DiarioHorario-Eólico'!AD670 -> 344.431 | Q30: ='Resumen-DiarioHorario-Eólico'!AD730 -> 405.73367 | R30: ='Resumen-DiarioHorario-Eólico'!AD790 -> 420.1335 | S30: ='Resumen-DiarioHorario-Eólico'!AD850 -> 441.09433 | T30: ='Resumen-DiarioHorario-Eólico'!AD910 -> 512.45467 | U30: ='Resumen-DiarioHorario-Eólico'!AD970 -> 472.797 | V30: ='Resumen-DiarioHorario-Eólico'!AD1030 -> 475.62083 | W30: ='Resumen-DiarioHorario-Eólico'!AD1090 -> 221.6385 | X30: ='Resumen-DiarioHorario-Eólico'!AD1150 -> 314.8525 | Y30: ='Resumen-DiarioHorario-Eólico'!AD1210 -> 260.79 | Z30: ='Resumen-DiarioHorario-Eólico'!AD1270 -> 148.784 | AA30: ='Resumen-DiarioHorario-Eólico'!AD1330 -> 229.3525 | AB30: ='Resumen-DiarioHorario-Eólico'!AD1390 -> 278.25383 | AC30: ='Resumen-DiarioHorario-Eólico'!AD1450 -> 241.03567 | AD30: ='Resumen-DiarioHorario-Eólico'!AD1510 -> 184.59217 | AE30: ='Resumen-DiarioHorario-Eólico'!AD1570 -> 190.696 | AF30: ='Resumen-DiarioHorario-Eólico'!AD1629 -> 298.95917 | AG30: ='Resumen-DiarioHorario-Eólico'!AD1688 -> 221.06017 | AH30: =+'Resumen-DiarioHorario-Eólico'!AD1747 -> 388.58083 | AI30: =+'Resumen-DiarioHorario-Eólico'!AD1806 -> 326.85417 | AK30: =SUM(E30:AI30) -> 9843.8628
B31: PE-CERROTIGRE | E31: ='Resumen-DiarioHorario-Eólico'!AD11 -> 670.11183 | F31: ='Resumen-DiarioHorario-Eólico'!AD71 -> 304.8725 | G31: ='Resumen-DiarioHorario-Eólico'!AD131 -> 504.32483 | H31: ='Resumen-DiarioHorario-Eólico'!AD191 -> 461.31817 | I31: ='Resumen-DiarioHorario-Eólico'!AD251 -> 201.71483 | J31: ='Resumen-DiarioHorario-Eólico'!AD311 -> 435.41367 | K31: ='Resumen-DiarioHorario-Eólico'!AD371 -> 308.612 | L31: ='Resumen-DiarioHorario-Eólico'!AD431 -> 366.0765 | M31: ='Resumen-DiarioHorario-Eólico'!AD491 -> 346.43717 | N31: ='Resumen-DiarioHorario-Eólico'!AD551 -> 409.35483 | O31: ='Resumen-DiarioHorario-Eólico'!AD611 -> 490.93567 | P31: ='Resumen-DiarioHorario-Eólico'!AD671 -> 476.97283 | Q31: ='Resumen-DiarioHorario-Eólico'!AD731 -> 118.4075 | R31: ='Resumen-DiarioHorario-Eólico'!AD791 -> 380.48467 | S31: ='Resumen-DiarioHorario-Eólico'!AD851 -> 400.63183 | T31: ='Resumen-DiarioHorario-Eólico'!AD911 -> 446.21917 | U31: ='Resumen-DiarioHorario-Eólico'!AD971 -> 543.29983 | V31: ='Resumen-DiarioHorario-Eólico'!AD1031 -> 577.16017 | W31: ='Resumen-DiarioHorario-Eólico'!AD1091 -> 275.58367 | X31: ='Resumen-DiarioHorario-Eólico'!AD1151 -> 361.03483 | Y31: ='Resumen-DiarioHorario-Eólico'!AD1211 -> 313.44567 | Z31: ='Resumen-DiarioHorario-Eólico'!AD1271 -> 193.8215 | AA31: ='Resumen-DiarioHorario-Eólico'!AD1331 -> 282.576 | AB31: ='Resumen-DiarioHorario-Eólico'!AD1391 -> 515.80333 | AC31: ='Resumen-DiarioHorario-Eólico'!AD1451 -> 251.09533 | AD31: ='Resumen-DiarioHorario-Eólico'!AD1511 -> 437.889 | AE31: ='Resumen-DiarioHorario-Eólico'!AD1571 -> 417.97983 | AF31: ='Resumen-DiarioHorario-Eólico'!AD1630 -> 397.99967 | AG31: ='Resumen-DiarioHorario-Eólico'!AD1689 -> 219.08817 | AH31: =+'Resumen-DiarioHorario-Eólico'!AD1748 -> 559.8475 | AI31: =+'Resumen-DiarioHorario-Eólico'!AD1807 -> 357.83133 | AK31: =SUM(E31:AI31) -> 12026.344
B32: PE-CALAMA | E32: ='Resumen-DiarioHorario-Eólico'!AD12 -> 413.7015 | F32: ='Resumen-DiarioHorario-Eólico'!AD72 -> 272.35367 | G32: ='Resumen-DiarioHorario-Eólico'!AD132 -> 432.70583 | H32: ='Resumen-DiarioHorario-Eólico'!AD192 -> 434.44383 | I32: ='Resumen-DiarioHorario-Eólico'!AD252 -> 287.12283 | J32: ='Resumen-DiarioHorario-Eólico'!AD312 -> 335.54033 | K32: ='Resumen-DiarioHorario-Eólico'!AD372 -> 254.113 | L32: ='Resumen-DiarioHorario-Eólico'!AD432 -> 302.11783 | M32: ='Resumen-DiarioHorario-Eólico'!AD492 -> 303.66367 | N32: ='Resumen-DiarioHorario-Eólico'!AD552 -> 297.2525 | O32: ='Resumen-DiarioHorario-Eólico'!AD612 -> 430.451 | P32: ='Resumen-DiarioHorario-Eólico'!AD672 -> 397.65283 | Q32: ='Resumen-DiarioHorario-Eólico'!AD732 -> 416.925 | R32: ='Resumen-DiarioHorario-Eólico'!AD792 -> 341.02533 | S32: ='Resumen-DiarioHorario-Eólico'!AD852 -> 298.678 | T32: ='Resumen-DiarioHorario-Eólico'!AD912 -> 389.3305 | U32: ='Resumen-DiarioHorario-Eólico'!AD972 -> 490.597 | V32: ='Resumen-DiarioHorario-Eólico'!AD1032 -> 475.91733 | W32: ='Resumen-DiarioHorario-Eólico'!AD1092 -> 319.27117 | X32: ='Resumen-DiarioHorario-Eólico'!AD1152 -> 441.37417 | Y32: ='Resumen-DiarioHorario-Eólico'!AD1212 -> 393.20467 | Z32: ='Resumen-DiarioHorario-Eólico'!AD1272 -> 141.66217 | AA32: ='Resumen-DiarioHorario-Eólico'!AD1332 -> 362.30767 | AB32: ='Resumen-DiarioHorario-Eólico'!AD1392 -> 315.84567 | AC32: ='Resumen-DiarioHorario-Eólico'!AD1452 -> 531.08433 | AD32: ='Resumen-DiarioHorario-Eólico'!AD1512 -> 820.53 | AE32: ='Resumen-DiarioHorario-Eólico'!AD1572 -> 0 | AF32: ='Resumen-DiarioHorario-Eólico'!AD1631 -> 0 | AG32: ='Resumen-DiarioHorario-Eólico'!AD1690 -> 189.15317 | AH32: =+'Resumen-DiarioHorario-Eólico'!AD1749 -> 411.08917 | AI32: =+'Resumen-DiarioHorario-Eólico'!AD1808 -> 327.8105 | AK32: =SUM(E32:AI32) -> 10826.925
B33: PE-TALTAL | E33: ='Resumen-DiarioHorario-Eólico'!AD13 -> 0 | F33: ='Resumen-DiarioHorario-Eólico'!AD73 -> 0 | G33: ='Resumen-DiarioHorario-Eólico'!AD133 -> 0 | H33: ='Resumen-DiarioHorario-Eólico'!AD193 -> 0 | I33: ='Resumen-DiarioHorario-Eólico'!AD253 -> 0 | J33: ='Resumen-DiarioHorario-Eólico'!AD313 -> 0 | K33: ='Resumen-DiarioHorario-Eólico'!AD373 -> 0 | L33: ='Resumen-DiarioHorario-Eólico'!AD433 -> 0 | M33: ='Resumen-DiarioHorario-Eólico'!AD493 -> 0 | N33: ='Resumen-DiarioHorario-Eólico'!AD553 -> 0 | O33: ='Resumen-DiarioHorario-Eólico'!AD613 -> 0 | P33: ='Resumen-DiarioHorario-Eólico'!AD673 -> 0 | Q33: ='Resumen-DiarioHorario-Eólico'!AD733 -> 0 | R33: ='Resumen-DiarioHorario-Eólico'!AD793 -> 0 | S33: ='Resumen-DiarioHorario-Eólico'!AD853 -> 0 | T33: ='Resumen-DiarioHorario-Eólico'!AD913 -> 0 | U33: ='Resumen-DiarioHorario-Eólico'!AD973 -> 0 | V33: ='Resumen-DiarioHorario-Eólico'!AD1033 -> 0 | W33: ='Resumen-DiarioHorario-Eólico'!AD1093 -> 0 | X33: ='Resumen-DiarioHorario-Eólico'!AD1153 -> 0 | Y33: ='Resumen-DiarioHorario-Eólico'!AD1213 -> 0 | Z33: ='Resumen-DiarioHorario-Eólico'!AD1273 -> 0 | AA33: ='Resumen-DiarioHorario-Eólico'!AD1333 -> 0 | AB33: ='Resumen-DiarioHorario-Eólico'!AD1393 -> 0 | AC33: ='Resumen-DiarioHorario-Eólico'!AD1453 -> 17.1535 | AD33: ='Resumen-DiarioHorario-Eólico'!AD1513 -> 0 | AE33: ='Resumen-DiarioHorario-Eólico'!AD1573 -> 0 | AF33: ='Resumen-DiarioHorario-Eólico'!AD1632 -> 0 | AG33: ='Resumen-DiarioHorario-Eólico'!AD1691 -> 0 | AH33: =+'Resumen-DiarioHorario-Eólico'!AD1750 -> 0 | AI33: =+'Resumen-DiarioHorario-Eólico'!AD1809 -> 0 | AK33: =SUM(E33:AI33) -> 17.1535
B34: PE-SARCO | E34: ='Resumen-DiarioHorario-Eólico'!AD14 -> 27.826833 | F34: ='Resumen-DiarioHorario-Eólico'!AD74 -> 43.668333 | G34: ='Resumen-DiarioHorario-Eólico'!AD134 -> 32.774167 | H34: ='Resumen-DiarioHorario-Eólico'!AD194 -> 21.650333 | I34: ='Resumen-DiarioHorario-Eólico'!AD254 -> 80.671333 | J34: ='Resumen-DiarioHorario-Eólico'!AD314 -> 35.072 | K34: ='Resumen-DiarioHorario-Eólico'!AD374 -> 8.5165 | L34: ='Resumen-DiarioHorario-Eólico'!AD434 -> 167.489 | M34: ='Resumen-DiarioHorario-Eólico'!AD494 -> 28.115833 | N34: ='Resumen-DiarioHorario-Eólico'!AD554 -> 3.1153333 | O34: ='Resumen-DiarioHorario-Eólico'!AD614 -> 117.11867 | P34: ='Resumen-DiarioHorario-Eólico'!AD674 -> 93.838333 | Q34: ='Resumen-DiarioHorario-Eólico'!AD734 -> 6.5223333 | R34: ='Resumen-DiarioHorario-Eólico'!AD794 -> 0 | S34: ='Resumen-DiarioHorario-Eólico'!AD854 -> 334.873 | T34: ='Resumen-DiarioHorario-Eólico'!AD914 -> 0 | U34: ='Resumen-DiarioHorario-Eólico'!AD974 -> 0 | V34: ='Resumen-DiarioHorario-Eólico'!AD1034 -> 0 | W34: ='Resumen-DiarioHorario-Eólico'!AD1094 -> 0 | X34: ='Resumen-DiarioHorario-Eólico'!AD1154 -> 0 | Y34: ='Resumen-DiarioHorario-Eólico'!AD1214 -> 21.88 | Z34: ='Resumen-DiarioHorario-Eólico'!AD1274 -> 0 | AA34: ='Resumen-DiarioHorario-Eólico'!AD1334 -> 23.482333 | AB34: ='Resumen-DiarioHorario-Eólico'!AD1394 -> 103.36733 | AC34: ='Resumen-DiarioHorario-Eólico'!AD1454 -> 81.295167 | AD34: ='Resumen-DiarioHorario-Eólico'!AD1514 -> 124.08717 | AE34: ='Resumen-DiarioHorario-Eólico'!AD1574 -> 165.34333 | AF34: ='Resumen-DiarioHorario-Eólico'!AD1633 -> 14.010667 | AG34: ='Resumen-DiarioHorario-Eólico'!AD1692 -> 35.640667 | AH34: =+'Resumen-DiarioHorario-Eólico'!AD1751 -> 103.05717 | AI34: =+'Resumen-DiarioHorario-Eólico'!AD1810 -> 52.457667 | AK34: =SUM(E34:AI34) -> 1725.8735
B35: PE-CABOLEONES-1 | E35: ='Resumen-DiarioHorario-Eólico'!AD15 -> 56.066833 | F35: ='Resumen-DiarioHorario-Eólico'!AD75 -> 87.116 | G35: ='Resumen-DiarioHorario-Eólico'!AD135 -> 11.225667 | H35: ='Resumen-DiarioHorario-Eólico'!AD195 -> 22.091333 | I35: ='Resumen-DiarioHorario-Eólico'!AD255 -> 61.169333 | J35: ='Resumen-DiarioHorario-Eólico'!AD315 -> 7.1208333 | K35: ='Resumen-DiarioHorario-Eólico'!AD375 -> 17.5325 | L35: ='Resumen-DiarioHorario-Eólico'!AD435 -> 34.017333 | M35: ='Resumen-DiarioHorario-Eólico'!AD495 -> 40.0695 | N35: ='Resumen-DiarioHorario-Eólico'!AD555 -> 12.698667 | O35: ='Resumen-DiarioHorario-Eólico'!AD615 -> 103.017 | P35: ='Resumen-DiarioHorario-Eólico'!AD675 -> 70.314667 | Q35: ='Resumen-DiarioHorario-Eólico'!AD735 -> 9.7466667 | R35: ='Resumen-DiarioHorario-Eólico'!AD795 -> 152.25033 | S35: ='Resumen-DiarioHorario-Eólico'!AD855 -> 29.31 | T35: ='Resumen-DiarioHorario-Eólico'!AD915 -> 19.2945 | U35: ='Resumen-DiarioHorario-Eólico'!AD975 -> 8.9348333 | V35: ='Resumen-DiarioHorario-Eólico'!AD1035 -> 53.8975 | W35: ='Resumen-DiarioHorario-Eólico'!AD1095 -> 15.9965 | X35: ='Resumen-DiarioHorario-Eólico'!AD1155 -> 5.2563333 | Y35: ='Resumen-DiarioHorario-Eólico'!AD1215 -> 13.712 | Z35: ='Resumen-DiarioHorario-Eólico'!AD1275 -> 7.4751667 | AA35: ='Resumen-DiarioHorario-Eólico'!AD1335 -> 15.808167 | AB35: ='Resumen-DiarioHorario-Eólico'!AD1395 -> 2.7833333 | AC35: ='Resumen-DiarioHorario-Eólico'!AD1455 -> 38.700833 | AD35: ='Resumen-DiarioHorario-Eólico'!AD1515 -> 66.467333 | AE35: ='Resumen-DiarioHorario-Eólico'!AD1575 -> 35.933667 | AF35: ='Resumen-DiarioHorario-Eólico'!AD1634 -> 4.0311667 | AG35: ='Resumen-DiarioHorario-Eólico'!AD1693 -> 55.572333 | AH35: =+'Resumen-DiarioHorario-Eólico'!AD1752 -> 118.37233 | AI35: =+'Resumen-DiarioHorario-Eólico'!AD1811 -> 22.784333 | AK35: =SUM(E35:AI35) -> 1198.767
B36: PE-CABOLEONES-2 | E36: ='Resumen-DiarioHorario-Eólico'!AD16 -> 231.89317 | F36: ='Resumen-DiarioHorario-Eólico'!AD76 -> 297.21117 | G36: ='Resumen-DiarioHorario-Eólico'!AD136 -> 177.66967 | H36: ='Resumen-DiarioHorario-Eólico'!AD196 -> 137.74183 | I36: ='Resumen-DiarioHorario-Eólico'!AD256 -> 239.91967 | J36: ='Resumen-DiarioHorario-Eólico'!AD316 -> 179.6615 | K36: ='Resumen-DiarioHorario-Eólico'!AD376 -> 67.400333 | L36: ='Resumen-DiarioHorario-Eólico'!AD436 -> 127.9535 | M36: ='Resumen-DiarioHorario-Eólico'!AD496 -> 204.15067 | N36: ='Resumen-DiarioHorario-Eólico'!AD556 -> 94.5525 | O36: ='Resumen-DiarioHorario-Eólico'!AD616 -> 297.765 | P36: ='Resumen-DiarioHorario-Eólico'!AD676 -> 248.11567 | Q36: ='Resumen-DiarioHorario-Eólico'!AD736 -> 46.117 | R36: ='Resumen-DiarioHorario-Eólico'!AD796 -> 305.75917 | S36: ='Resumen-DiarioHorario-Eólico'!AD856 -> 225.9025 | T36: ='Resumen-DiarioHorario-Eólico'!AD916 -> 226.56483 | U36: ='Resumen-DiarioHorario-Eólico'!AD976 -> 98.429333 | V36: ='Resumen-DiarioHorario-Eólico'!AD1036 -> 285.31667 | W36: ='Resumen-DiarioHorario-Eólico'!AD1096 -> 250.08167 | X36: ='Resumen-DiarioHorario-Eólico'!AD1156 -> 64.665 | Y36: ='Resumen-DiarioHorario-Eólico'!AD1216 -> 134.09117 | Z36: ='Resumen-DiarioHorario-Eólico'!AD1276 -> 138.06783 | AA36: ='Resumen-DiarioHorario-Eólico'!AD1336 -> 105.88483 | AB36: ='Resumen-DiarioHorario-Eólico'!AD1396 -> 146.6655 | AC36: ='Resumen-DiarioHorario-Eólico'!AD1456 -> 122.56417 | AD36: ='Resumen-DiarioHorario-Eólico'!AD1516 -> 237.42417 | AE36: ='Resumen-DiarioHorario-Eólico'!AD1576 -> 236.25083 | AF36: ='Resumen-DiarioHorario-Eólico'!AD1635 -> 211.18367 | AG36: ='Resumen-DiarioHorario-Eólico'!AD1694 -> 98.324333 | AH36: =+'Resumen-DiarioHorario-Eólico'!AD1753 -> 352.23967 | AI36: =+'Resumen-DiarioHorario-Eólico'!AD1812 -> 198.172 | AK36: =SUM(E36:AI36) -> 5787.739
B37: PE-CABOLEONES-3 | E37: ='Resumen-DiarioHorario-Eólico'!AD17 -> 29.7235 | F37: ='Resumen-DiarioHorario-Eólico'!AD77 -> 46.859667 | G37: ='Resumen-DiarioHorario-Eólico'!AD137 -> 25.919667 | H37: ='Resumen-DiarioHorario-Eólico'!AD197 -> 3.7838333 | I37: ='Resumen-DiarioHorario-Eólico'!AD257 -> 44.312333 | J37: ='Resumen-DiarioHorario-Eólico'!AD317 -> 9.9231667 | K37: ='Resumen-DiarioHorario-Eólico'!AD377 -> 17.416833 | L37: ='Resumen-DiarioHorario-Eólico'!AD437 -> 34.154167 | M37: ='Resumen-DiarioHorario-Eólico'!AD497 -> 41.840333 | N37: ='Resumen-DiarioHorario-Eólico'!AD557 -> 9.4696667 | O37: ='Resumen-DiarioHorario-Eólico'!AD617 -> 133.36317 | P37: ='Resumen-DiarioHorario-Eólico'!AD677 -> 69.337 | Q37: ='Resumen-DiarioHorario-Eólico'!AD737 -> 6.7433333 | R37: ='Resumen-DiarioHorario-Eólico'!AD797 -> 116.99233 | S37: ='Resumen-DiarioHorario-Eólico'!AD857 -> 97.658 | T37: ='Resumen-DiarioHorario-Eólico'!AD917 -> 3.4938333 | U37: ='Resumen-DiarioHorario-Eólico'!AD977 -> 7.0061667 | V37: ='Resumen-DiarioHorario-Eólico'!AD1037 -> 39.8095 | W37: ='Resumen-DiarioHorario-Eólico'!AD1097 -> 37.3055 | X37: ='Resumen-DiarioHorario-Eólico'!AD1157 -> 5.2525 | Y37: ='Resumen-DiarioHorario-Eólico'!AD1217 -> 2.8433333 | Z37: ='Resumen-DiarioHorario-Eólico'!AD1277 -> 2.9535 | AA37: ='Resumen-DiarioHorario-Eólico'!AD1337 -> 11.429333 | AB37: ='Resumen-DiarioHorario-Eólico'!AD1397 -> 2.5996667 | AC37: ='Resumen-DiarioHorario-Eólico'!AD1457 -> 38.031667 | AD37: ='Resumen-DiarioHorario-Eólico'!AD1517 -> 39.788167 | AE37: ='Resumen-DiarioHorario-Eólico'!AD1577 -> 30.019667 | AF37: ='Resumen-DiarioHorario-Eólico'!AD1636 -> 1.7996667 | AG37: ='Resumen-DiarioHorario-Eólico'!AD1695 -> 33.467333 | AH37: =+'Resumen-DiarioHorario-Eólico'!AD1754 -> 127.84433 | AI37: =+'Resumen-DiarioHorario-Eólico'!AD1813 -> 26.466333 | AK37: =SUM(E37:AI37) -> 1097.6075
B38: PE-SANJUAN | E38: ='Resumen-DiarioHorario-Eólico'!AD18 -> 129.331 | F38: ='Resumen-DiarioHorario-Eólico'!AD78 -> 129.64233 | G38: ='Resumen-DiarioHorario-Eólico'!AD138 -> 445.901 | H38: ='Resumen-DiarioHorario-Eólico'!AD198 -> 146.9635 | I38: ='Resumen-DiarioHorario-Eólico'!AD258 -> 567.12783 | J38: ='Resumen-DiarioHorario-Eólico'!AD318 -> 30.682167 | K38: ='Resumen-DiarioHorario-Eólico'!AD378 -> 398.33983 | L38: ='Resumen-DiarioHorario-Eólico'!AD438 -> 928.64617 | M38: ='Resumen-DiarioHorario-Eólico'!AD498 -> 140.09133 | N38: ='Resumen-DiarioHorario-Eólico'!AD558 -> 72.098 | O38: ='Resumen-DiarioHorario-Eólico'!AD618 -> 229.51217 | P38: ='Resumen-DiarioHorario-Eólico'!AD678 -> 291.23067 | Q38: ='Resumen-DiarioHorario-Eólico'!AD738 -> 332.13517 | R38: ='Resumen-DiarioHorario-Eólico'!AD798 -> 144.3155 | S38: ='Resumen-DiarioHorario-Eólico'!AD858 -> 233.27967 | T38: ='Resumen-DiarioHorario-Eólico'!AD918 -> 920.07967 | U38: ='Resumen-DiarioHorario-Eólico'!AD978 -> 472.87917 | V38: ='Resumen-DiarioHorario-Eólico'!AD1038 -> 16.229333 | W38: ='Resumen-DiarioHorario-Eólico'!AD1098 -> 0.36316667 | X38: ='Resumen-DiarioHorario-Eólico'!AD1158 -> 0.38333333 | Y38: ='Resumen-DiarioHorario-Eólico'!AD1218 -> 24.287 | Z38: ='Resumen-DiarioHorario-Eólico'!AD1278 -> 69.598167 | AA38: ='Resumen-DiarioHorario-Eólico'!AD1338 -> 7.9305 | AB38: ='Resumen-DiarioHorario-Eólico'!AD1398 -> 273.774 | AC38: ='Resumen-DiarioHorario-Eólico'!AD1458 -> 10.687333 | AD38: ='Resumen-DiarioHorario-Eólico'!AD1518 -> 315.75883 | AE38: ='Resumen-DiarioHorario-Eólico'!AD1578 -> 1020.647 | AF38: ='Resumen-DiarioHorario-Eólico'!AD1637 -> 251.3095 | AG38: ='Resumen-DiarioHorario-Eólico'!AD1696 -> 45.335667 | AH38: =+'Resumen-DiarioHorario-Eólico'!AD1755 -> 822.68783 | AI38: =+'Resumen-DiarioHorario-Eólico'!AD1814 -> 557.5675 | AK38: =SUM(E38:AI38) -> 9028.8143
B39: PE-PUNTACOLORADA | E39: ='Resumen-DiarioHorario-Eólico'!AD19 -> 0 | F39: ='Resumen-DiarioHorario-Eólico'!AD79 -> 0 | G39: ='Resumen-DiarioHorario-Eólico'!AD139 -> 0 | H39: ='Resumen-DiarioHorario-Eólico'!AD199 -> 0 | I39: ='Resumen-DiarioHorario-Eólico'!AD259 -> 0 | J39: ='Resumen-DiarioHorario-Eólico'!AD319 -> 0 | K39: ='Resumen-DiarioHorario-Eólico'!AD379 -> 0 | L39: ='Resumen-DiarioHorario-Eólico'!AD439 -> 0 | M39: ='Resumen-DiarioHorario-Eólico'!AD499 -> 0 | N39: ='Resumen-DiarioHorario-Eólico'!AD559 -> 0 | O39: ='Resumen-DiarioHorario-Eólico'!AD619 -> 0 | P39: ='Resumen-DiarioHorario-Eólico'!AD679 -> 0 | Q39: ='Resumen-DiarioHorario-Eólico'!AD739 -> 0 | R39: ='Resumen-DiarioHorario-Eólico'!AD799 -> 0 | S39: ='Resumen-DiarioHorario-Eólico'!AD859 -> 0 | T39: ='Resumen-DiarioHorario-Eólico'!AD919 -> 0 | U39: ='Resumen-DiarioHorario-Eólico'!AD979 -> 0 | V39: ='Resumen-DiarioHorario-Eólico'!AD1039 -> 0 | W39: ='Resumen-DiarioHorario-Eólico'!AD1099 -> 0 | X39: ='Resumen-DiarioHorario-Eólico'!AD1159 -> 0 | Y39: ='Resumen-DiarioHorario-Eólico'!AD1219 -> 0 | Z39: ='Resumen-DiarioHorario-Eólico'!AD1279 -> 0 | AA39: ='Resumen-DiarioHorario-Eólico'!AD1339 -> 0 | AB39: ='Resumen-DiarioHorario-Eólico'!AD1399 -> 0 | AC39: ='Resumen-DiarioHorario-Eólico'!AD1459 -> 0 | AD39: ='Resumen-DiarioHorario-Eólico'!AD1519 -> 0 | AE39: ='Resumen-DiarioHorario-Eólico'!AD1579 -> 0 | AF39: ='Resumen-DiarioHorario-Eólico'!AD1638 -> 0 | AG39: ='Resumen-DiarioHorario-Eólico'!AD1697 -> 0 | AH39: =+'Resumen-DiarioHorario-Eólico'!AD1756 -> 0 | AI39: =+'Resumen-DiarioHorario-Eólico'!AD1815 -> 0 | AK39: =SUM(E39:AI39) -> 0
... B72: PE-ATACAMA | E72: ='Resumen-DiarioHorario-Eólico'!AD52 -> 104.135 | F72: ='Resumen-DiarioHorario-Eólico'!AD112 -> 97.9875 | G72: ='Resumen-DiarioHorario-Eólico'!AD172 -> 409.95717 | H72: ='Resumen-DiarioHorario-Eólico'!AD232 -> 377.435 | I72: ='Resumen-DiarioHorario-Eólico'!AD292 -> 167.79333 | J72: ='Resumen-DiarioHorario-Eólico'!AD352 -> 364.69617 | K72: ='Resumen-DiarioHorario-Eólico'!AD412 -> 97.6935 | L72: ='Resumen-DiarioHorario-Eólico'!AD472 -> 499.43967 | M72: ='Resumen-DiarioHorario-Eólico'!AD532 -> 42.841333 | N72: ='Resumen-DiarioHorario-Eólico'!AD592 -> 21.101333 | O72: ='Resumen-DiarioHorario-Eólico'!AD652 -> 357.581 | P72: ='Resumen-DiarioHorario-Eólico'!AD712 -> 301.17817 | Q72: ='Resumen-DiarioHorario-Eólico'!AD772 -> 104.17933 | R72: ='Resumen-DiarioHorario-Eólico'!AD832 -> 261.52067 | S72: ='Resumen-DiarioHorario-Eólico'!AD892 -> 747.836 | T72: ='Resumen-DiarioHorario-Eólico'!AD952 -> 498.21983 | U72: ='Resumen-DiarioHorario-Eólico'!AD1012 -> 220.25367 | V72: ='Resumen-DiarioHorario-Eólico'!AD1072 -> 80.4785 | W72: ='Resumen-DiarioHorario-Eólico'!AD1132 -> 15.517 | X72: ='Resumen-DiarioHorario-Eólico'!AD1192 -> 0.041166667 | Y72: ='Resumen-DiarioHorario-Eólico'!AD1252 -> 96.892 | Z72: ='Resumen-DiarioHorario-Eólico'!AD1312 -> 322.8885 | AA72: ='Resumen-DiarioHorario-Eólico'!AD1372 -> 138.88417 | AB72: ='Resumen-DiarioHorario-Eólico'!AD1432 -> 126.68883 | AC72: ='Resumen-DiarioHorario-Eólico'!AD1492 -> 1.0511667 | AD72: ='Resumen-DiarioHorario-Eólico'!AD1552 -> 595.1755 | AE72: ='Resumen-DiarioHorario-Eólico'!AD1612 -> 743.39783 | AF72: ='Resumen-DiarioHorario-Eólico'!AD1671 -> 230.76033 | AG72: ='Resumen-DiarioHorario-Eólico'!AD1730 -> 2.3003333 | AH72: =+'Resumen-DiarioHorario-Eólico'!AD1789 -> 706.89283 | AI72: =+'Resumen-DiarioHorario-Eólico'!AD1848 -> 495.51083 | AK72: =SUM(E72:AI72) -> 8230.3277
B73: PE-LACABANA | D73: † | E73: ='Resumen-DiarioHorario-Eólico'!AD53 -> 0 | F73: ='Resumen-DiarioHorario-Eólico'!AD113 -> 0 | G73: ='Resumen-DiarioHorario-Eólico'!AD173 -> 0 | H73: ='Resumen-DiarioHorario-Eólico'!AD233 -> 0 | I73: ='Resumen-DiarioHorario-Eólico'!AD293 -> 0 | J73: ='Resumen-DiarioHorario-Eólico'!AD353 -> 120.95417 | K73: ='Resumen-DiarioHorario-Eólico'!AD413 -> 0 | L73: ='Resumen-DiarioHorario-Eólico'!AD473 -> 0 | M73: ='Resumen-DiarioHorario-Eólico'!AD533 -> 0 | N73: ='Resumen-DiarioHorario-Eólico'!AD593 -> 0 | O73: ='Resumen-DiarioHorario-Eólico'!AD653 -> 0 | P73: ='Resumen-DiarioHorario-Eólico'!AD713 -> 0 | Q73: ='Resumen-DiarioHorario-Eólico'!AD773 -> 0 | R73: ='Resumen-DiarioHorario-Eólico'!AD833 -> 0 | S73: ='Resumen-DiarioHorario-Eólico'!AD893 -> 0 | T73: ='Resumen-DiarioHorario-Eólico'!AD953 -> 0 | U73: ='Resumen-DiarioHorario-Eólico'!AD1013 -> 0 | V73: ='Resumen-DiarioHorario-Eólico'!AD1073 -> 0 | W73: ='Resumen-DiarioHorario-Eólico'!AD1133 -> 0 | X73: ='Resumen-DiarioHorario-Eólico'!AD1193 -> 0 | Y73: ='Resumen-DiarioHorario-Eólico'!AD1253 -> 0 | Z73: ='Resumen-DiarioHorario-Eólico'!AD1313 -> 0 | AA73: ='Resumen-DiarioHorario-Eólico'!AD1373 -> 0 | AB73: ='Resumen-DiarioHorario-Eólico'!AD1433 -> 0 | AC73: ='Resumen-DiarioHorario-Eólico'!AD1493 -> 0 | AD73: ='Resumen-DiarioHorario-Eólico'!AD1553 -> 0 | AE73: ='Resumen-DiarioHorario-Eólico'!AD1613 -> 0 | AF73: ='Resumen-DiarioHorario-Eólico'!AD1672 -> 0 | AG73: ='Resumen-DiarioHorario-Eólico'!AD1731 -> 0 | AH73: =+'Resumen-DiarioHorario-Eólico'!AD1790 -> 0 | AI73: =+'Resumen-DiarioHorario-Eólico'!AD1849 -> 0 | AK73: =SUM(E73:AI73) -> 120.95417
B74: PE-SANMATIAS | E74: ='Resumen-DiarioHorario-Eólico'!AD54 -> 103.0815 | F74: ='Resumen-DiarioHorario-Eólico'!AD114 -> 206.79833 | G74: ='Resumen-DiarioHorario-Eólico'!AD174 -> 4.1428333 | H74: ='Resumen-DiarioHorario-Eólico'!AD234 -> 33.62 | I74: ='Resumen-DiarioHorario-Eólico'!AD294 -> 0.11633333 | J74: ='Resumen-DiarioHorario-Eólico'!AD354 -> 1.6135 | K74: ='Resumen-DiarioHorario-Eólico'!AD414 -> 25.8555 | L74: ='Resumen-DiarioHorario-Eólico'!AD474 -> 34.613667 | M74: ='Resumen-DiarioHorario-Eólico'!AD534 -> 89.857833 | N74: ='Resumen-DiarioHorario-Eólico'!AD594 -> 377.6025 | O74: ='Resumen-DiarioHorario-Eólico'!AD654 -> 64.263833 | P74: ='Resumen-DiarioHorario-Eólico'!AD714 -> 29.0475 | Q74: ='Resumen-DiarioHorario-Eólico'!AD774 -> 67.165167 | R74: ='Resumen-DiarioHorario-Eólico'!AD834 -> 47.267833 | S74: ='Resumen-DiarioHorario-Eólico'!AD894 -> 6.5645 | T74: ='Resumen-DiarioHorario-Eólico'!AD954 -> 83.195167 | U74: ='Resumen-DiarioHorario-Eólico'!AD1014 -> 162.16317 | V74: ='Resumen-DiarioHorario-Eólico'!AD1074 -> 193.84583 | W74: ='Resumen-DiarioHorario-Eólico'!AD1134 -> 3.4071667 | X74: ='Resumen-DiarioHorario-Eólico'!AD1194 -> 1.9783333 | Y74: ='Resumen-DiarioHorario-Eólico'!AD1254 -> 10.396667 | Z74: ='Resumen-DiarioHorario-Eólico'!AD1314 -> 9.6211667 | AA74: ='Resumen-DiarioHorario-Eólico'!AD1374 -> 0.055833333 | AB74: ='Resumen-DiarioHorario-Eólico'!AD1434 -> 12.418167 | AC74: ='Resumen-DiarioHorario-Eólico'!AD1494 -> 59.085667 | AD74: ='Resumen-DiarioHorario-Eólico'!AD1554 -> 1.9866667 | AE74: ='Resumen-DiarioHorario-Eólico'!AD1614 -> 1.2533333 | AF74: ='Resumen-DiarioHorario-Eólico'!AD1673 -> 64.975833 | AG74: ='Resumen-DiarioHorario-Eólico'!AD1732 -> 11.011167 | AH74: =+'Resumen-DiarioHorario-Eólico'!AD1791 -> 30.338833 | AI74: =+'Resumen-DiarioHorario-Eólico'!AD1850 -> 110.85133 | AK74: =SUM(E74:AI74) -> 1848.1952
B75: PE-CARDONAL | E75: ='Resumen-DiarioHorario-Eólico'!AD55 -> 4.1146083 | F75: ='Resumen-DiarioHorario-Eólico'!AD115 -> 3.0038717 | G75: ='Resumen-DiarioHorario-Eólico'!AD175 -> 2.15209 | H75: ='Resumen-DiarioHorario-Eólico'!AD235 -> 37.214392 | I75: ='Resumen-DiarioHorario-Eólico'!AD295 -> 0.14176167 | J75: ='Resumen-DiarioHorario-Eólico'!AD355 -> 3.0560333 | K75: ='Resumen-DiarioHorario-Eólico'!AD415 -> 6.2398883 | L75: ='Resumen-DiarioHorario-Eólico'!AD475 -> 2.0975833 | M75: ='Resumen-DiarioHorario-Eólico'!AD535 -> 2.8848083 | N75: ='Resumen-DiarioHorario-Eólico'!AD595 -> 2.2738 | O75: ='Resumen-DiarioHorario-Eólico'!AD655 -> 9.0710917 | P75: ='Resumen-DiarioHorario-Eólico'!AD715 -> 10.739245 | Q75: ='Resumen-DiarioHorario-Eólico'!AD775 -> 24.632917 | R75: ='Resumen-DiarioHorario-Eólico'!AD835 -> 17.988322 | S75: ='Resumen-DiarioHorario-Eólico'!AD895 -> 15.485305 | T75: ='Resumen-DiarioHorario-Eólico'!AD955 -> 13.904485 | U75: ='Resumen-DiarioHorario-Eólico'!AD1015 -> 47.864947 | V75: ='Resumen-DiarioHorario-Eólico'!AD1075 -> 1.7729633 | W75: ='Resumen-DiarioHorario-Eólico'!AD1135 -> 0.35356333 | X75: ='Resumen-DiarioHorario-Eólico'!AD1195 -> 0.74479833 | Y75: ='Resumen-DiarioHorario-Eólico'!AD1255 -> 7.4785983 | Z75: ='Resumen-DiarioHorario-Eólico'!AD1315 -> 1.8736733 | AA75: ='Resumen-DiarioHorario-Eólico'!AD1375 -> 3.1150917 | AB75: ='Resumen-DiarioHorario-Eólico'!AD1435 -> 5.8880983 | AC75: ='Resumen-DiarioHorario-Eólico'!AD1495 -> 9.7546567 | AD75: ='Resumen-DiarioHorario-Eólico'!AD1555 -> 1.8675483 | AE75: ='Resumen-DiarioHorario-Eólico'!AD1615 -> 2.6975267 | AF75: ='Resumen-DiarioHorario-Eólico'!AD1674 -> 0 | AG75: ='Resumen-DiarioHorario-Eólico'!AD1733 -> 0.13033 | AH75: =+'Resumen-DiarioHorario-Eólico'!AD1792 -> 0 | AI75: =+'Resumen-DiarioHorario-Eólico'!AD1851 -> 7.1593 | AK75: =SUM(E75:AI75) -> 245.7013
B76: PE-CERRILLOS | E76: ='Resumen-DiarioHorario-Eólico'!AD56 -> 11.79158 | F76: ='Resumen-DiarioHorario-Eólico'!AD116 -> 4.68265 | G76: ='Resumen-DiarioHorario-Eólico'!AD176 -> 2.2519267 | H76: ='Resumen-DiarioHorario-Eólico'!AD236 -> 34.99194 | I76: ='Resumen-DiarioHorario-Eólico'!AD296 -> 0.02737 | J76: ='Resumen-DiarioHorario-Eólico'!AD356 -> 3.5616 | K76: ='Resumen-DiarioHorario-Eólico'!AD416 -> 10.158223 | L76: ='Resumen-DiarioHorario-Eólico'!AD476 -> 1.3775 | M76: ='Resumen-DiarioHorario-Eólico'!AD536 -> 8.4363333 | N76: ='Resumen-DiarioHorario-Eólico'!AD596 -> 2.81469 | O76: ='Resumen-DiarioHorario-Eólico'!AD656 -> 22.971373 | P76: ='Resumen-DiarioHorario-Eólico'!AD716 -> 27.194213 | Q76: ='Resumen-DiarioHorario-Eólico'!AD776 -> 43.76492 | R76: ='Resumen-DiarioHorario-Eólico'!AD836 -> 30.170797 | S76: ='Resumen-DiarioHorario-Eólico'!AD896 -> 28.389853 | T76: ='Resumen-DiarioHorario-Eólico'!AD956 -> 29.164707 | U76: ='Resumen-DiarioHorario-Eólico'!AD1016 -> 46.878657 | V76: ='Resumen-DiarioHorario-Eólico'!AD1076 -> 2.3106533 | W76: ='Resumen-DiarioHorario-Eólico'!AD1136 -> 0.035523333 | X76: ='Resumen-DiarioHorario-Eólico'!AD1196 -> 1.66157 | Y76: ='Resumen-DiarioHorario-Eólico'!AD1256 -> 4.21314 | Z76: ='Resumen-DiarioHorario-Eólico'!AD1316 -> 1.0988933 | AA76: ='Resumen-DiarioHorario-Eólico'!AD1376 -> 0.21391333 | AB76: ='Resumen-DiarioHorario-Eólico'!AD1436 -> 3.5315333 | AC76: ='Resumen-DiarioHorario-Eólico'!AD1496 -> 8.47452 | AD76: ='Resumen-DiarioHorario-Eólico'!AD1556 -> 1.80957 | AE76: ='Resumen-DiarioHorario-Eólico'!AD1616 -> 8.5964633 | AF76: ='Resumen-DiarioHorario-Eólico'!AD1675 -> 0 | AG76: ='Resumen-DiarioHorario-Eólico'!AD1734 -> 0 | AH76: =+'Resumen-DiarioHorario-Eólico'!AD1793 -> 0 | AI76: =+'Resumen-DiarioHorario-Eólico'!AD1852 -> 4.2730867 | AK76: =SUM(E76:AI76) -> 344.8472
B77: PE-MANANTIALES | E77: ='Resumen-DiarioHorario-Eólico'!AD57 -> 35.999925 | F77: ='Resumen-DiarioHorario-Eólico'!AD117 -> 17.549115 | G77: ='Resumen-DiarioHorario-Eólico'!AD177 -> 10.545543 | H77: ='Resumen-DiarioHorario-Eólico'!AD237 -> 71.16311 | I77: ='Resumen-DiarioHorario-Eólico'!AD297 -> 0.084035 | J77: ='Resumen-DiarioHorario-Eólico'!AD357 -> 10.42592 | K77: ='Resumen-DiarioHorario-Eólico'!AD417 -> 32.340408 | L77: ='Resumen-DiarioHorario-Eólico'!AD477 -> 3.70425 | M77: ='Resumen-DiarioHorario-Eólico'!AD537 -> 30.664393 | N77: ='Resumen-DiarioHorario-Eólico'!AD597 -> 14.585437 | O77: ='Resumen-DiarioHorario-Eólico'!AD657 -> 35.637573 | P77: ='Resumen-DiarioHorario-Eólico'!AD717 -> 34.394445 | Q77: ='Resumen-DiarioHorario-Eólico'!AD777 -> 61.454563 | R77: ='Resumen-DiarioHorario-Eólico'!AD837 -> 64.461518 | S77: ='Resumen-DiarioHorario-Eólico'!AD897 -> 29.595003 | T77: ='Resumen-DiarioHorario-Eólico'!AD957 -> 39.531735 | U77: ='Resumen-DiarioHorario-Eólico'!AD1017 -> 76.382445 | V77: ='Resumen-DiarioHorario-Eólico'!AD1077 -> 17.296683 | W77: ='Resumen-DiarioHorario-Eólico'!AD1137 -> 8.0889233 | X77: ='Resumen-DiarioHorario-Eólico'!AD1197 -> 6.9331033 | Y77: ='Resumen-DiarioHorario-Eólico'!AD1257 -> 18.11744 | Z77: ='Resumen-DiarioHorario-Eólico'!AD1317 -> 5.477 | AA77: ='Resumen-DiarioHorario-Eólico'!AD1377 -> 1.0739417 | AB77: ='Resumen-DiarioHorario-Eólico'!AD1437 -> 11.167385 | AC77: ='Resumen-DiarioHorario-Eólico'!AD1497 -> 16.309608 | AD77: ='Resumen-DiarioHorario-Eólico'!AD1557 -> 3.7899783 | AE77: ='Resumen-DiarioHorario-Eólico'!AD1617 -> 10.431333 | AF77: ='Resumen-DiarioHorario-Eólico'!AD1676 -> 0 | AG77: ='Resumen-DiarioHorario-Eólico'!AD1735 -> 0 | AH77: =+'Resumen-DiarioHorario-Eólico'!AD1794 -> 0 | AI77: =+'Resumen-DiarioHorario-Eólico'!AD1853 -> 16.585562 | AK77: =SUM(E77:AI77) -> 683.79038
B78: PE-KALLPA | E78: ='Resumen-DiarioHorario-Eólico'!AD58 -> 742.2496 | F78: ='Resumen-DiarioHorario-Eólico'!AD118 -> 460.48327 | G78: ='Resumen-DiarioHorario-Eólico'!AD178 -> 307.55295 | H78: ='Resumen-DiarioHorario-Eólico'!AD238 -> 605.467 | I78: ='Resumen-DiarioHorario-Eólico'!AD298 -> 13.381833 | J78: ='Resumen-DiarioHorario-Eólico'!AD358 -> 824.71717 | K78: ='Resumen-DiarioHorario-Eólico'!AD418 -> 857.43975 | L78: ='Resumen-DiarioHorario-Eólico'!AD478 -> 72.711533 | M78: ='Resumen-DiarioHorario-Eólico'!AD538 -> 811.55733 | N78: ='Resumen-DiarioHorario-Eólico'!AD598 -> 587.02033 | O78: ='Resumen-DiarioHorario-Eólico'!AD658 -> 1026.2209 | P78: ='Resumen-DiarioHorario-Eólico'!AD718 -> 569.78013 | Q78: ='Resumen-DiarioHorario-Eólico'!AD778 -> 576.0635 | R78: ='Resumen-DiarioHorario-Eólico'!AD838 -> 1098.9166 | S78: ='Resumen-DiarioHorario-Eólico'!AD898 -> 853.86933 | T78: ='Resumen-DiarioHorario-Eólico'!AD958 -> 630.67698 | U78: ='Resumen-DiarioHorario-Eólico'!AD1018 -> 579.03815 | V78: ='Resumen-DiarioHorario-Eólico'!AD1078 -> 1050.0922 | W78: ='Resumen-DiarioHorario-Eólico'!AD1138 -> 87.361 | X78: ='Resumen-DiarioHorario-Eólico'!AD1198 -> 63.8485 | Y78: ='Resumen-DiarioHorario-Eólico'!AD1258 -> 732.01013 | Z78: ='Resumen-DiarioHorario-Eólico'!AD1318 -> 856.65243 | AA78: ='Resumen-DiarioHorario-Eólico'!AD1378 -> 82.663 | AB78: ='Resumen-DiarioHorario-Eólico'!AD1438 -> 740.40817 | AC78: ='Resumen-DiarioHorario-Eólico'!AD1498 -> 1010.9635 | AD78: ='Resumen-DiarioHorario-Eólico'!AD1558 -> 308.96978 | AE78: ='Resumen-DiarioHorario-Eólico'!AD1618 -> 215.7685 | AF78: ='Resumen-DiarioHorario-Eólico'!AD1677 -> 708.15375 | AG78: ='Resumen-DiarioHorario-Eólico'!AD1736 -> 471.02297 | AH78: =+'Resumen-DiarioHorario-Eólico'!AD1795 -> 868.04862 | AI78: =+'Resumen-DiarioHorario-Eólico'!AD1854 -> 434.3574 | AK78: =SUM(E78:AI78) -> 18247.466
B79: PE-HORIZONTENORTE | E79: ='Resumen-DiarioHorario-Eólico'!AD59 -> 487.00643 | F79: ='Resumen-DiarioHorario-Eólico'!AD119 -> 301.45093 | G79: ='Resumen-DiarioHorario-Eólico'!AD179 -> 380.03247 | H79: ='Resumen-DiarioHorario-Eólico'!AD239 -> 394.73075 | I79: ='Resumen-DiarioHorario-Eólico'!AD299 -> 443.51217 | J79: ='Resumen-DiarioHorario-Eólico'!AD359 -> 1010.4725 | K79: ='Resumen-DiarioHorario-Eólico'!AD419 -> 721.4835 | L79: ='Resumen-DiarioHorario-Eólico'!AD479 -> 161.47123 | M79: ='Resumen-DiarioHorario-Eólico'!AD539 -> 932.91567 | N79: ='Resumen-DiarioHorario-Eólico'!AD599 -> 913.0887 | O79: ='Resumen-DiarioHorario-Eólico'!AD659 -> 506.66133 | P79: ='Resumen-DiarioHorario-Eólico'!AD719 -> 65.27655 | Q79: ='Resumen-DiarioHorario-Eólico'!AD779 -> 623.5292 | R79: ='Resumen-DiarioHorario-Eólico'!AD839 -> 1219.3492 | S79: ='Resumen-DiarioHorario-Eólico'!AD899 -> 312.49767 | T79: ='Resumen-DiarioHorario-Eólico'!AD959 -> 17.0907 | U79: ='Resumen-DiarioHorario-Eólico'!AD1019 -> 146.47667 | V79: ='Resumen-DiarioHorario-Eólico'!AD1079 -> 183.71795 | W79: ='Resumen-DiarioHorario-Eólico'!AD1139 -> 191.77603 | X79: ='Resumen-DiarioHorario-Eólico'!AD1199 -> 137.35643 | Y79: ='Resumen-DiarioHorario-Eólico'!AD1259 -> 244.81808 | Z79: ='Resumen-DiarioHorario-Eólico'!AD1319 -> 114.84528 | AA79: ='Resumen-DiarioHorario-Eólico'!AD1379 -> 98.942717 | AB79: ='Resumen-DiarioHorario-Eólico'!AD1439 -> 552.43427 | AC79: ='Resumen-DiarioHorario-Eólico'!AD1499 -> 784.82086 | AD79: ='Resumen-DiarioHorario-Eólico'!AD1559 -> 341.67375 | AE79: ='Resumen-DiarioHorario-Eólico'!AD1619 -> 143.57327 | AF79: ='Resumen-DiarioHorario-Eólico'!AD1678 -> 211.87833 | AG79: ='Resumen-DiarioHorario-Eólico'!AD1737 -> 69.482 | AH79: =+'Resumen-DiarioHorario-Eólico'!AD1796 -> 398.21333 | AI79: =+'Resumen-DiarioHorario-Eólico'!AD1855 -> 136.5516 | AK79: =SUM(E79:AI79) -> 12247.13
B80: PE-HORIZONTESUR | E80: ='Resumen-DiarioHorario-Eólico'!AD60 -> 376.9157 | F80: ='Resumen-DiarioHorario-Eólico'!AD120 -> 149.43703 | G80: ='Resumen-DiarioHorario-Eólico'!AD180 -> 388.24992 | H80: ='Resumen-DiarioHorario-Eólico'!AD240 -> 599.52875 | I80: ='Resumen-DiarioHorario-Eólico'!AD300 -> 263.37817 | J80: ='Resumen-DiarioHorario-Eólico'!AD360 -> 609.32565 | K80: ='Resumen-DiarioHorario-Eólico'!AD420 -> 580.5396 | L80: ='Resumen-DiarioHorario-Eólico'!AD480 -> 259.36807 | M80: ='Resumen-DiarioHorario-Eólico'!AD540 -> 598.22877 | N80: ='Resumen-DiarioHorario-Eólico'!AD600 -> 490.42302 | O80: ='Resumen-DiarioHorario-Eólico'!AD660 -> 458.35042 | P80: ='Resumen-DiarioHorario-Eólico'!AD720 -> 131.19517 | Q80: ='Resumen-DiarioHorario-Eólico'!AD780 -> 2.5685 | R80: ='Resumen-DiarioHorario-Eólico'!AD840 -> 234.703 | S80: ='Resumen-DiarioHorario-Eólico'!AD900 -> 109.63817 | T80: ='Resumen-DiarioHorario-Eólico'!AD960 -> 39.172167 | U80: ='Resumen-DiarioHorario-Eólico'!AD1020 -> 81.013167 | V80: ='Resumen-DiarioHorario-Eólico'!AD1080 -> 128.82205 | W80: ='Resumen-DiarioHorario-Eólico'!AD1140 -> 285.65367 | X80: ='Resumen-DiarioHorario-Eólico'!AD1200 -> 324.07253 | Y80: ='Resumen-DiarioHorario-Eólico'!AD1260 -> 404.07583 | Z80: ='Resumen-DiarioHorario-Eólico'!AD1320 -> 187.74143 | AA80: ='Resumen-DiarioHorario-Eólico'!AD1380 -> 182.23847 | AB80: ='Resumen-DiarioHorario-Eólico'!AD1440 -> 437.32678 | AC80: ='Resumen-DiarioHorario-Eólico'!AD1500 -> 366.2415 | AD80: ='Resumen-DiarioHorario-Eólico'!AD1560 -> 214.70787 | AE80: ='Resumen-DiarioHorario-Eólico'!AD1620 -> 177.80803 | AF80: ='Resumen-DiarioHorario-Eólico'!AD1679 -> 141.64192 | AG80: ='Resumen-DiarioHorario-Eólico'!AD1738 -> 16.768667 | AH80: =+'Resumen-DiarioHorario-Eólico'!AD1797 -> 568.42307 | AI80: =+'Resumen-DiarioHorario-Eólico'!AD1856 -> 286.79513 | AK80: =SUM(E80:AI80) -> 9094.3522
B81: PE-PUNTADETALCA | E81: ='Resumen-DiarioHorario-Eólico'!AD61 -> 25.069167 | F81: ='Resumen-DiarioHorario-Eólico'!AD121 -> 22.874167 | G81: ='Resumen-DiarioHorario-Eólico'!AD181 -> 20.611167 | H81: ='Resumen-DiarioHorario-Eólico'!AD241 -> 26.630833 | I81: ='Resumen-DiarioHorario-Eólico'!AD301 -> 0 | J81: ='Resumen-DiarioHorario-Eólico'!AD361 -> 26.7155 | K81: ='Resumen-DiarioHorario-Eólico'!AD421 -> 23.784333 | L81: ='Resumen-DiarioHorario-Eólico'!AD481 -> 64.675667 | M81: ='Resumen-DiarioHorario-Eólico'!AD541 -> 0.0275 | N81: ='Resumen-DiarioHorario-Eólico'!AD601 -> 0.013833333 | O81: ='Resumen-DiarioHorario-Eólico'!AD661 -> 1.4375 | P81: ='Resumen-DiarioHorario-Eólico'!AD721 -> 46.119333 | Q81: ='Resumen-DiarioHorario-Eólico'!AD781 -> 28.026 | R81: ='Resumen-DiarioHorario-Eólico'!AD841 -> 78.389167 | S81: ='Resumen-DiarioHorario-Eólico'!AD901 -> 99.212333 | T81: ='Resumen-DiarioHorario-Eólico'!AD961 -> 49.199 | U81: ='Resumen-DiarioHorario-Eólico'!AD1021 -> 34.522333 | V81: ='Resumen-DiarioHorario-Eólico'!AD1081 -> 6.1903333 | W81: ='Resumen-DiarioHorario-Eólico'!AD1141 -> 25.8205 | X81: ='Resumen-DiarioHorario-Eólico'!AD1201 -> 7.9748333 | Y81: ='Resumen-DiarioHorario-Eólico'!AD1261 -> 2.6568333 | Z81: ='Resumen-DiarioHorario-Eólico'!AD1321 -> 44.339333 | AA81: ='Resumen-DiarioHorario-Eólico'!AD1381 -> 16.592833 | AB81: ='Resumen-DiarioHorario-Eólico'!AD1441 -> 2.4518333 | AC81: ='Resumen-DiarioHorario-Eólico'!AD1501 -> 51.9575 | AD81: ='Resumen-DiarioHorario-Eólico'!AD1561 -> 62.804 | AE81: ='Resumen-DiarioHorario-Eólico'!AD1621 -> 48.1605 | AF81: ='Resumen-DiarioHorario-Eólico'!AD1680 -> 18.409667 | AG81: ='Resumen-DiarioHorario-Eólico'!AD1739 -> 3.485 | AH81: =+'Resumen-DiarioHorario-Eólico'!AD1798 -> 115.60883 | AI81: =+'Resumen-DiarioHorario-Eólico'!AD1857 -> 1.308 | AK81: =SUM(E81:AI81) -> 955.06783
...

Sheet Resumen-DiarioHorario-Eólico
B2: CURTAILMENTS EÓLICAS POR CENTRALES EN FORMA DIARIA/HORARIA
B5: ='Resumen-Mensual'!$E$26 -> 46023
B7: Central/Hora | E7: 1 | F7: 2 | G7: 3 | H7: 4 | I7: 5 | J7: 6 | K7: 7 | L7: 8 | M7: 9 | N7: 10 | O7: 11 | P7: 12 | Q7: 13 | R7: 14 | S7: 15 | T7: 16 | U7: 17 | V7: 18 | W7: 19 | X7: 20 | Y7: 21 | Z7: 22 | AA7: 23 | AB7: 24 | AC7: Total
B8: PE-TCHAMMA | E8: 0 | F8: 0 | G8: 0 | H8: 0 | I8: 0 | J8: 0 | K8: 0 | L8: 13.3955 | M8: 37.648833 | N8: 52.376833 | O8: 10.860167 | P8: 0.46566667 | Q8: 19.315667 | R8: 23.392333 | S8: 30.0095 | T8: 20.194833 | U8: 28.629667 | V8: 57.157833 | W8: 53.765 | X8: 38.5165 | Y8: 0 | Z8: 0 | AA8: 0 | AB8: 0 | AD8: =SUM(E8:AB8) -> 385.72833
B9: PE-SIERRAGORDA | E9: 0 | F9: 0 | G9: 0 | H9: 0 | I9: 0 | J9: 0 | K9: 0 | L9: 1.6946667 | M9: 3.5136667 | N9: 9.6811667 | O9: 5.69 | P9: 9.1383333 | Q9: 23.239667 | R9: 6.4126667 | S9: 10.689 | T9: 37.805833 | U9: 52.1545 | V9: 64.821 | W9: 48.259667 | X9: 39.679667 | Y9: 0 | Z9: 0 | AA9: 0 | AB9: 0 | AD9: =SUM(E9:AB9) -> 312.77983
B10: PE-VALLEDELOSVIENTOS | E10: 0 | F10: 0 | G10: 0 | H10: 0 | I10: 0 | J10: 0 | K10: 0 | L10: 2.097 | M10: 6.53 | N10: 3.89 | O10: 2.67 | P10: 8.56 | Q10: 26.54 | R10: 16.81 | S10: 28.92 | T10: 35.74 | U10: 36.68 | V10: 36.25 | W10: 35.08 | X10: 61.4975 | Y10: 0 | Z10: 0 | AA10: 0 | AB10: 0 | AD10: =SUM(E10:AB10) -> 301.2645
B11: PE-CERROTIGRE | E11: 0 | F11: 0 | G11: 0 | H11: 0 | I11: 0 | J11: 0 | K11: 0 | L11: 0.9 | M11: 3 | N11: 0.9 | O11: 2.5535 | P11: 7.6216667 | Q11: 41.188333 | R11: 60.633667 | S11: 85.570667 | T11: 77.983333 | U11: 86.520667 | V11: 98.465 | W11: 113.54533 | X11: 91.229667 | Y11: 0 | Z11: 0 | AA11: 0 | AB11: 0 | AD11: =SUM(E11:AB11) -> 670.11183
B12: PE-CALAMA | E12: 0 | F12: 0 | G12: 0 | H12: 0 | I12: 0 | J12: 0 | K12: 0 | L12: 1.5885 | M12: 5.8675 | N12: 2.218 | O12: 3.2303333 | P12: 5.1328333 | Q12: 20.125333 | R12: 29.099333 | S12: 57.440167 | T12: 81.55 | U12: 87.474833 | V12: 99.164333 | W12: 13.902333 | X12: 6.908 | Y12: 0 | Z12: 0 | AA12: 0 | AB12: 0 | AD12: =SUM(E12:AB12) -> 413.7015
B13: PE-TALTAL | E13: 0 | F13: 0 | G13: 0 | H13: 0 | I13: 0 | J13: 0 | K13: 0 | L13: 0 | M13: 0 | N13: 0 | O13: 0 | P13: 0 | Q13: 0 | R13: 0 | S13: 0 | T13: 0 | U13: 0 | V13: 0 | W13: 0 | X13: 0 | Y13: 0 | Z13: 0 | AA13: 0 | AB13: 0 | AD13: =SUM(E13:AB13) -> 0
B14: PE-SARCO | E14: 0 | F14: 0 | G14: 0 | H14: 0 | I14: 0 | J14: 0 | K14: 0 | L14: 0 | M14: 0 | N14: 0.92616667 | O14: 6.3496667 | P14: 8.9258333 | Q14: 5.8636667 | R14: 2.5471667 | S14: 0.011166667 | T14: 0 | U14: 0.2935 | V14: 0.3685 | W14: 0 | X14: 2.5411667 | Y14: 0 | Z14: 0 | AA14: 0 | AB14: 0 | AD14: =SUM(E14:AB14) -> 27.826833
B15: PE-CABOLEONES-1 | E15: 0 | F15: 0 | G15: 0 | H15: 0 | I15: 0 | J15: 0 | K15: 0 | L15: 0 | M15: 0 | N15: 2.103 | O15: 6.7346667 | P15: 8.7565 | Q15: 11.441 | R15: 9.6458333 | S15: 5.3943333 | T15: 4.5911667 | U15: 0.71216667 | V15: 0.096666667 | W15: 6.2305 | X15: 0.361 | Y15: 0 | Z15: 0 | AA15: 0 | AB15: 0 | AD15: =SUM(E15:AB15) -> 56.066833
B16: PE-CABOLEONES-2 | E16: 0 | F16: 0 | G16: 0 | H16: 0 | I16: 0 | J16: 0 | K16: 0 | L16: 0 | M16: 0 | N16: 4.1841667 | O16: 11.681667 | P16: 16.262333 | Q16: 28.395333 | R16: 27.9935 | S16: 28.34 | T16: 26.165333 | U16: 19.577333 | V16: 20.556167 | W16: 21.9665 | X16: 26.770833 | Y16: 0 | Z16: 0 | AA16: 0 | AB16: 0 | AD16: =SUM(E16:AB16) -> 231.89317
B17: PE-CABOLEONES-3 | E17: 0 | F17: 0 | G17: 0 | H17: 0 | I17: 0 | J17: 0 | K17: 0 | L17: 0 | M17: 0 | N17: 0.39066667 | O17: 5.565 | P17: 6.4288333 | Q17: 6.2226667 | R17: 3.7916667 | S17: 2.3495 | T17: 1.7205 | U17: 0 | V17: 0 | W17: 0 | X17: 3.2546667 | Y17: 0 | Z17: 0 | AA17: 0 | AB17: 0 | AD17: =SUM(E17:AB17) -> 29.7235
B18: PE-SANJUAN | E18: 0 | F18: 0 | G18: 0 | H18: 0 | I18: 0 | J18: 0 | K18: 0 | L18: 0 | M18: 0 | N18: 0 | O18: 0.060833333 | P18: 2.0288333 | Q18: 2.08 | R18: 1.0626667 | S18: 2.74 | T18: 1.072 | U18: 0 | V18: 0 | W18: 39.553 | X18: 80.733667 | Y18: 0 | Z18: 0 | AA18: 0 | AB18: 0 | AD18: =SUM(E18:AB18) -> 129.331
B19: PE-PUNTACOLORADA | E19: 0 | F19: 0 | G19: 0 | H19: 0 | I19: 0 | J19: 0 | K19: 0 | L19: 0 | M19: 0 | N19: 0 | O19: 0 | P19: 0 | Q19: 0 | R19: 0 | S19: 0 | T19: 0 | U19: 0 | V19: 0 | W19: 0 | X19: 0 | Y19: 0 | Z19: 0 | AA19: 0 | AB19: 0 | AD19: =SUM(E19:AB19) -> 0
... B61: PE-PUNTADETALCA | E61: 0 | F61: 0 | G61: 0 | H61: 0 | I61: 0 | J61: 0 | K61: 0 | L61: 0.53766667 | M61: 0.6715 | N61: 0 | O61: 2.8041667 | P61: 1.1173333 | Q61: 4.5535 | R61: 2.1715 | S61: 0.0076666667 | T61: 0.96633333 | U61: 3.7458333 | V61: 3.1078333 | W61: 2.4895 | X61: 2.8963333 | Y61: 0 | Z61: 0 | AA61: 0 | AB61: 0 | AD61: =SUM(E61:AB61) -> 25.069167
B62: Total | E62: =SUM(E8:E61) -> 0 | F62: =SUM(F8:F61) -> 0 | G62: =SUM(G8:G61) -> 0 | H62: =SUM(H8:H61) -> 0 | I62: =SUM(I8:I61) -> 0 | J62: =SUM(J8:J61) -> 0 | K62: =SUM(K8:K61) -> 0 | L62: =SUM(L8:L61) -> 148.676 | ... AB62: =SUM(AB8:AB61) -> 0 | AC62: =SUM(AC8:AE61) -> 10434.53
B65: ='Resumen-Mensual'!$F$26 -> 46024
B67: Central/Hora | E67: 1 | F67: 2 | G67: 3 | H67: 4 | I67: 5 | J67: 6 | K67: 7 | L67: 8 | M67: 9 | N67: 10 | O67: 11 | P67: 12 | Q67: 13 | R67: 14 | S67: 15 | T67: 16 | U67: 17 | V67: 18 | W67: 19 | X67: 20 | Y67: 21 | Z67: 22 | AA67: 23 | AB67: 24 | AC67: Total
B68: PE-TCHAMMA | E68: 0 | F68: 0 | G68: 0 | H68: 0 | I68: 0 | J68: 0 | K68: 0 | L68: 0 | M68: 1.6505 | N68: 41.452167 | O68: 10.357333 | P68: 0.49533333 | Q68: 4.628 | R68: 1.5638333 | S68: 11.898 | T68: 15.280667 | U68: 22.097833 | V68: 45.9675 | W68: 60.673667 | X68: 7.0008333 | Y68: 0 | Z68: 0 | AA68: 0 | AB68: 0 | AD68: =SUM(E68:AB68) -> 223.06567
B69: PE-SIERRAGORDA | E69: 0 | F69: 0 | G69: 0 | H69: 0 | I69: 0 | J69: 0 | K69: 0 | L69: 1.0755 | M69: 7.1913333 | N69: 9.8446667 | O69: 4.924 | P69: 8.7763333 | Q69: 5.6551667 | R69: 0.4665 | S69: 0 | T69: 16.221 | U69: 26.8865 | V69: 37.028 | W69: 36.268667 | X69: 13.815333 | Y69: 0 | Z69: 0 | AA69: 0 | AB69: 0 | AD69: =SUM(E69:AB69) -> 168.153
B70: PE-VALLEDELOSVIENTOS | E70: 0 | F70: 0 | G70: 0 | H70: 0 | I70: 0 | J70: 0 | K70: 0 | L70: 2.2135 | M70: 6.53 | N70: 3.89 | O70: 2.67 | P70: 8.56 | Q70: 26.54 | R70: 53.44 | S70: 26.91 | T70: 33.73 | U70: 34.67 | V70: 34.24 | W70: 33.07 | X70: 8.5 | Y70: 0 | Z70: 0 | AA70: 0 | AB70: 0 | AD70: =SUM(E70:AB70) -> 274.9635
B71: PE-CERROTIGRE | E71: 0 | F71: 0 | G71: 0 | H71: 0 | I71: 0 | J71: 0 | K71: 0 | L71: 1.3616667 | M71: 4.9 | N71: 0.3 | O71: 5.1 | P71: 13.909 | Q71: 28.321 | R71: 15.135667 | S71: 11.349167 | T71: 27.008333 | U71: 44.103333 | V71: 48.79 | W71: 75.961167 | X71: 28.633167 | Y71: 0 | Z71: 0 | AA71: 0 | AB71: 0 | AD71: =SUM(E71:AB71) -> 304.8725
B72: PE-CALAMA | E72: 0 | F72: 0 | G72: 0 | H72: 0 | I72: 0 | J72: 0 | K72: 0 | L72: 2.6163333 | M72: 6.4448333 | N72: 4.2676667 | O72: 3.3838333 | P72: 6.5485 | Q72: 14.117833 | R72: 21.330333 | S72: 23.078333 | T72: 35.4305 | U72: 49.863 | V72: 48.771167 | W72: 56.501333 | X72: 0 | Y72: 0 | Z72: 0 | AA72: 0 | AB72: 0 | AD72: =SUM(E72:AB72) -> 272.35367
B73: PE-TALTAL | E73: 0 | F73: 0 | G73: 0 | H73: 0 | I73: 0 | J73: 0 | K73: 0 | L73: 0 | M73: 0 | N73: 0 | O73: 0 | P73: 0 | Q73: 0 | R73: 0 | S73: 0 | T73: 0 | U73: 0 | V73: 0 | W73: 0 | X73: 0 | Y73: 0 | Z73: 0 | AA73: 0 | AB73: 0 | AD73: =SUM(E73:AB73) -> 0
B74: PE-SARCO | E74: 0 | F74: 0 | G74: 0 | H74: 0 | I74: 0 | J74: 0 | K74: 0 | L74: 1.4405 | M74: 9.7126667 | N74: 7.6855 | O74: 6.7913333 | P74: 4.8266667 | Q74: 1.4663333 | R74: 0.77616667 | S74: 0 | T74: 0 | U74: 0.044166667 | V74: 3.1528333 | W74: 2.6955 | X74: 5.0766667 | Y74: 0 | Z74: 0 | AA74: 0 | AB74: 0 | AD74: =SUM(E74:AB74) -> 43.668333
B75: PE-CABOLEONES-1 | E75: 0 | F75: 0 | G75: 0 | H75: 0 | I75: 0 | J75: 0 | K75: 0 | L75: 2.3068333 | M75: 11.775667 | N75: 12.257333 | O75: 13.063833 | P75: 12.265667 | Q75: 10.8635 | R75: 6.8235 | S75: 1.3086667 | T75: 4.7025 | U75: 6.3083333 | V75: 5.4401667 | W75: 0 | X75: 0 | Y75: 0 | Z75: 0 | AA75: 0 | AB75: 0 | AD75: =SUM(E75:AB75) -> 87.116
B76: PE-CABOLEONES-2 | E76: 0 | F76: 0 | G76: 0 | H76: 0 | I76: 0 | J76: 0 | K76: 0 | L76: 5.7013333 | M76: 19.300167 | N76: 20.999333 | O76: 25.675833 | P76: 27.090333 | Q76: 28.633167 | R76: 24.186833 | S76: 20.2485 | T76: 24.654333 | U76: 30.599 | V76: 30.807667 | W76: 22.799667 | X76: 16.515 | Y76: 0 | Z76: 0 | AA76: 0 | AB76: 0 | AD76: =SUM(E76:AB76) -> 297.21117
B77: PE-CABOLEONES-3 | E77: 0 | F77: 0 | G77: 0 | H77: 0 | I77: 0 | J77: 0 | K77: 0 | L77: 1.4311667 | M77: 9.1748333 | N77: 7.873 | O77: 8.3175 | P77: 7.0865 | Q77: 3.3893333 | R77: 0.721 | S77: 0.036166667 | T77: 2.1043333 | U77: 1.7406667 | V77: 1.9423333 | W77: 0 | X77: 3.0428333 | Y77: 0 | Z77: 0 | AA77: 0 | AB77: 0 | AD77: =SUM(E77:AB77) -> 46.859667
B78: PE-SANJUAN | E78: 0 | F78: 0 | G78: 0 | H78: 0 | I78: 0 | J78: 0 | K78: 0 | L78: 1.7606667 | M78: 5.06 | N78: 4.08 | O78: 3.6858333 | P78: 2.1765 | Q78: 0.631 | R78: 0 | S78: 0 | T78: 0 | U78: 0 | V78: 2.432 | W78: 62.172833 | X78: 47.6435 | Y78: 0 | Z78: 0 | AA78: 0 | AB78: 0 | AD78: =SUM(E78:AB78) -> 129.64233
B79: PE-PUNTACOLORADA | E79: 0 | F79: 0 | G79: 0 | H79: 0 | I79: 0 | J79: 0 | K79: 0 | L79: 0 | M79: 0 | N79: 0 | O79: 0 | P79: 0 | Q79: 0 | R79: 0 | S79: 0 | T79: 0 | U79: 0 | V79: 0 | W79: 0 | X79: 0 | Y79: 0 | Z79: 0 | AA79: 0 | AB79: 0 | AD79: =SUM(E79:AB79) -> 0
... B121: PE-PUNTADETALCA | E121: 0 | F121: 0 | G121: 0 | H121: 0 | I121: 0 | J121: 0 | K121: 0 | L121: 0.608 | M121: 2.659 | N121: 1.3251667 | O121: 2.5015 | P121: 3.3743333 | Q121: 4.5988333 | R121: 0.67166667 | S121: 0 | T121: 0 | U121: 0.12166667 | V121: 2.0768333 | W121: 3.0661667 | X121: 1.871 | Y121: 0 | Z121: 0 | AA121: 0 | AB121: 0 | AD121: =SUM(E121:AB121) -> 22.874167
B122: Total | E122: =SUM(E68:E121) -> 0 | F122: =SUM(F68:F121) -> 0 | G122: =SUM(G68:G121) -> 0 | H122: =SUM(H68:H121) -> 0 | I122: =SUM(I68:I121) -> 0 | J122: =SUM(J68:J121) -> 0 | K122: =SUM(K68:K121) -> 0 | L122: =SUM(L68:L121) -> 112.99483 | ... AB122: =SUM(AB68:AB121) -> 0 | AC122: =SUM(AC68:AE121) -> 8132.6799
B125: ='Resumen-Mensual'!$G$26 -> 46025
B127: Central/Hora | E127: 1 | F127: 2 | G127: 3 | H127: 4 | I127: 5 | J127: 6 | K127: 7 | L127: 8 | M127: 9 | N127: 10 | O127: 11 | P127: 12 | Q127: 13 | R127: 14 | S127: 15 | T127: 16 | U127: 17 | V127: 18 | W127: 19 | X127: 20 | Y127: 21 | Z127: 22 | AA127: 23 | AB127: 24 | AC127: Total
B128: PE-TCHAMMA | E128: 0 | F128: 0 | G128: 0 | H128: 0 | I128: 0 | J128: 0 | K128: 0 | L128: 0 | M128: 0.296 | N128: 2.3603333 | O128: 6.3988333 | P128: 9.7538333 | Q128: 19.637333 | R128: 19.145333 | S128: 14.298667 | T128: 27.698 | U128: 33.805667 | V128: 17.785333 | W128: 37.537167 | X128: 29.2 | Y128: 0 | Z128: 0 | AA128: 0 | AB128: 0 | AD128: =SUM(E128:AB128) -> 217.9165
B129: PE-SIERRAGORDA | E129: 0 | F129: 0 | G129: 0 | H129: 0 | I129: 0 | J129: 0 | K129: 0 | L129: 0 | M129: 16.000667 | N129: 9.9365 | O129: 4.104 | P129: 6.5668333 | Q129: 8.4436667 | R129: 15.997667 | S129: 18.676 | T129: 33.545 | U129: 5.542 | V129: 61.7735 | W129: 31.568667 | X129: 18.026667 | Y129: 0 | Z129: 0 | AA129: 0 | AB129: 0 | AD129: =SUM(E129:AB129) -> 230.18117
B130: PE-VALLEDELOSVIENTOS | E130: 0 | F130: 0 | G130: 0 | H130: 0 | I130: 0 | J130: 0 | K130: 0 | L130: 0 | M130: 3.4806667 | N130: 2.465 | O130: 3.38 | P130: 13.46 | Q130: 39.72 | R130: 67.86 | S130: 47.89 | T130: 54.4 | U130: 54.04 | V130: 54.27 | W130: 53.72 | X130: 52.5135 | Y130: 0 | Z130: 0 | AA130: 0 | AB130: 0 | AD130: =SUM(E130:AB130) -> 447.19917
B131: PE-CERROTIGRE | E131: 0 | F131: 0 | G131: 0 | H131: 0 | I131: 0 | J131: 0 | K131: 0 | L131: 0 | M131: 4.83 | N131: 2.21 | O131: 9.3 | P131: 16.063667 | Q131: 19.853667 | R131: 24.978833 | S131: 43.865833 | T131: 64.229333 | U131: 80.2675 | V131: 72.5195 | W131: 99.294333 | X131: 66.912167 | Y131: 0 | Z131: 0 | AA131: 0 | AB131: 0 | AD131: =SUM(E131:AB131) -> 504.32483
B132: PE-CALAMA | E132: 0 | F132: 0 | G132: 0 | H132: 0 | I132: 0 | J132: 0 | K132: 0 | L132: 0 | M132: 11.961 | N132: 2.9656667 | O132: 2.2051667 | P132: 12.860833 | Q132: 30.976 | R132: 59.979833 | S132: 47.259 | T132: 63.384167 | U132: 70.977 | V132: 70.527833 | W132: 31.927667 | X132: 27.681667 | Y132: 0 | Z132: 0 | AA132: 0 | AB132: 0 | AD132: =SUM(E132:AB132) -> 432.70583
...

Sheet Resumen-DiarioHorario-Solar
B2: CURTAILMENTS SOLAR POR CENTRALES EN FORMA DIARIA/HORARIA
B5: ='Resumen-Mensual'!$E$26 -> 46023
B7: Central/Hora | E7: 1 | F7: 2 | G7: 3 | H7: 4 | I7: 5 | J7: 6 | K7: 7 | L7: 8 | M7: 9 | N7: 10 | O7: 11 | P7: 12 | Q7: 13 | R7: 14 | S7: 15 | T7: 16 | U7: 17 | V7: 18 | W7: 19 | X7: 20 | Y7: 21 | Z7: 22 | AA7: 23 | AB7: 24 | AC7: Total
B8: PFV-POZOALMONTE-2 | E8: 0 | F8: 0 | G8: 0 | H8: 0 | I8: 0 | J8: 0 | K8: 0 | L8: 0.95333333 | M8: 1.53 | N8: 1.18 | O8: 1.36 | P8: 1.21 | Q8: 1.27 | R8: 1.09 | S8: 1.19 | T8: 1.06 | U8: 0.99 | V8: 0.84 | W8: 0.41 | X8: 1.615 | Y8: 0 | Z8: 0 | AA8: 0 | AB8: 0 | AD8: =SUM(E8:AB8) -> 14.698333
B9: PFV-POZOALMONTE-3 | E9: 0 | F9: 0 | G9: 0 | H9: 0 | I9: 0 | J9: 0 | K9: 0 | L9: 0.95333333 | M9: 5.86 | N9: 5.57 | O9: 6.08 | P9: 5.88 | Q9: 5.9 | R9: 5.68 | S9: 5.49 | T9: 5.35 | U9: 5.03 | V9: 4.46 | W9: 3.54 | X9: 2.635 | Y9: 0 | Z9: 0 | AA9: 0 | AB9: 0 | AD9: =SUM(E9:AB9) -> 62.428333
B10: PFV-LAHUAYCA-2 | E10: 0 | F10: 0 | G10: 0 | H10: 0 | I10: 0 | J10: 0 | K10: 0 | L10: 0.396 | M10: 1.2971667 | N10: 1.8616667 | O10: 0.9195 | P10: 3.14 | Q10: 3.9221667 | R10: 3.5251667 | S10: 2.9086667 | T10: 2.9535 | U10: 3.008 | V10: 1.2385 | W10: 0.057 | X10: 0.41933333 | Y10: 0 | Z10: 0 | AA10: 0 | AB10: 0 | AD10: =SUM(E10:AB10) -> 25.646667
B11: PFV-SANTAISABEL | E11: 0 | F11: 0 | G11: 0 | H11: 0 | I11: 0 | J11: 0 | K11: 0 | L11: 10.213333 | M11: 69.013667 | N11: 103.09717 | O11: 107.9005 | P11: 110.0345 | Q11: 111.24333 | R11: 107.5195 | S11: 102.27017 | T11: 101.257 | U11: 90.766167 | V11: 84.973833 | W11: 62.154833 | X11: 12.593 | Y11: 0 | Z11: 0 | AA11: 0 | AB11: 0 | AD11: =SUM(E11:AB11) -> 1073.037
B12: PFV-HUATACONDO | E12: 0 | F12: 0 | G12: 0 | H12: 0 | I12: 0 | J12: 0 | K12: 0 | L12: 0 | M12: 0 | N12: 0 | O12: 0 | P12: 0 | Q12: 0 | R12: 0 | S12: 0 | T12: 0 | U12: 0 | V12: 0 | W12: 0 | X12: 0 | Y12: 0 | Z12: 0 | AA12: 0 | AB12: 0 | AD12: =SUM(E12:AB12) -> 0
B13: PFV-ATACAMASOLAR-2 | E13: 0 | F13: 0 | G13: 0 | H13: 0 | I13: 0 | J13: 0 | K13: 0 | L13: 3.2866667 | M13: 5.974 | N13: 30.500333 | O13: 37.6105 | P13: 43.658 | Q13: 44.080667 | R13: 46.000833 | S13: 43.182 | T13: 56.226667 | U13: 60.562333 | V13: 21.262833 | W13: 65.876667 | X13: 20.587 | Y13: 0 | Z13: 0 | AA13: 0 | AB13: 0 | AD13: =SUM(E13:AB13) -> 478.8085
B14: PFV-NUEVOQUILLAGUA | E14: 0 | F14: 0 | G14: 0 | H14: 0 | I14: 0 | J14: 0 | K14: 0 | L14: 0 | M14: 0 | N14: 0 | O14: 0 | P14: 0 | Q14: 0 | R14: 0 | S14: 0 | T14: 0 | U14: 0 | V14: 0 | W14: 0 | X14: 0 | Y14: 0 | Z14: 0 | AA14: 0 | AB14: 0 | AD14: =SUM(E14:AB14) -> 0
